Workbook

Sheet 01# Mar
D1: Carniceria "La Veronica"
D3: Jesus Manuel Romo Alba R.F.C. ROAJ600629RQ5
D4: C. ALEGRIA #211 BARRIO DEL ENCINO C. P. 20240 AGUASCALIENTES, AGS.
D5: 44572 | E5: Folio No. 9000
B7: NOMBRE: | D7: H.G.Z. No. 1
B8: DOMICILIO:
B9: CIUDAD: | D9: AGUASCALIENTES
B11: Suma de Nota Martes
B12: No. | C12: Martes | D12: Producto | E12: C. Unit. | F12: Total
B13: 7 | C13: 11.48 | D13: PECHUGA DE POLLO DESHUESADA | E13: 150 | F13: 1722
B14: 8 | C14: 0.96 | D14: PECHUGA DESHUESADA EN BISTEC | E14: 150 | F14: 144
B15: 10 | C15: 19.8 | D15: PIERNA Y MUSLO DE POLLO SIN PIEL EN FORMA DE PISTOLA | E15: 75 | F15: 1485
B16: 15 | C16: 10.8 | D16: FALDA DE RES | E16: 140 | F16: 1512
B17: 16 | C17: 13.2 | D17: PULPA DE RES EN TROZO | E17: 145 | F17: 1914
B18: 17 | C18: 8.1 | D18: PULPA DE RES MOLIDA | E18: 130 | F18: 1053
B19: 18 | C19: 10.29 | D19: HUEVO ENTERO | E19: 38 | F19: 391.02
B20: 20 | C20: 0.66 | D20: JAMÓN DE PAVO | E20: 120 | F20: 79.2
B21: 21 | C21: 1.88 | D21: JAMÓN DE PECHUGA DE PAVO | E21: 140 | F21: 263.2
B22: 24 | C22: 1.72 | D22: SALCHICHA DE PAVO VIENA | E22: 50 | F22: 86
B23: Total general | F23: 8649.42

Sheet 01# Mier
D1: Carniceria "La Veronica"
D3: Jesus Manuel Romo Alba R.F.C. ROAJ600629RQ5
D4: C. ALEGRIA #211 BARRIO DEL ENCINO C. P. 20240 AGUASCALIENTES, AGS.
D5: 44573 | E5: Folio No. 8370
B7: NOMBRE: | D7: H.G.Z. No. 1
B8: DOMICILIO:
B9: CIUDAD: | D9: AGUASCALIENTES
B11: Suma de Nota Miercoles
B12: No. | C12: Miercoles | D12: Producto | E12: C. Unit. | F12: Total
B13: 7 | C13: 20.08 | D13: PECHUGA DE POLLO DESHUESADA | E13: 150 | F13: 3012
B14: 8 | C14: 3.6 | D14: PECHUGA DESHUESADA EN BISTEC | E14: 150 | F14: 540
B15: 10 | C15: 21.15 | D15: PIERNA Y MUSLO DE POLLO SIN PIEL EN FORMA DE PISTOLA | E15: 75 | F15: 1586.25
B16: 12 | C16: 12 | D16: BISTEC DE PIERNA DE RES | E16: 160 | F16: 1920
B17: 17 | C17: 1.14 | D17: PULPA DE RES MOLIDA | E17: 130 | F17: 148.2
B18: 18 | C18: 0.76 | D18: HUEVO ENTERO | E18: 38 | F18: 28.88
B19: Total general | F19: 7235.33

Sheet 01# Juev
D1: Carniceria "La Veronica"
D3: Jesus Manuel Romo Alba R.F.C. ROAJ600629RQ5
D4: C. ALEGRIA #211 BARRIO DEL ENCINO C. P. 20240 AGUASCALIENTES, AGS.
D5: 44574 | E5: Folio No. 8380
B7: NOMBRE: | D7: H.G.Z. No. 1
B8: DOMICILIO:
B9: CIUDAD: | D9: AGUASCALIENTES
B11: Suma de Nota Jueves
B12: No. | C12: Jueves | D12: Producto | E12: C. Unit. | F12: Total
B13: 3 | C13: 14.4 | D13: PIERNA DE CERDO EN TROZO | E13: 82 | F13: 1180.8
B14: 7 | C14: 0.72 | D14: PECHUGA DE POLLO DESHUESADA | E14: 150 | F14: 108
B15: 8 | C15: 17.4 | D15: PECHUGA DESHUESADA EN BISTEC | E15: 150 | F15: 2610
B16: 12 | C16: 10 | D16: BISTEC DE PIERNA DE RES | E16: 160 | F16: 1600
B17: 17 | C17: 11.22 | D17: PULPA DE RES MOLIDA | E17: 130 | F17: 1458.6
B18: 18 | C18: 21.5 | D18: HUEVO ENTERO | E18: 38 | F18: 817
B19: 23 | C19: 3 | D19: SALCHICHA DE CERDO VIENA | E19: 40 | F19: 120
B20: 24 | C20: 6 | D20: SALCHICHA DE PAVO VIENA | E20: 50 | F20: 300
B21: 25 | C21: 1 | D21: TOCINO | E21: 140 | F21: 140
B22: Total general | F22: 8334.4

Sheet 01# Viern
D1: Carniceria "La Veronica"
D3: Jesus Manuel Romo Alba R.F.C. ROAJ600629RQ5
D4: C. ALEGRIA #211 BARRIO DEL ENCINO C. P. 20240 AGUASCALIENTES, AGS.
D5: 44575 | E5: Folio No. 8000
B7: NOMBRE: | D7: H.G.Z. No. 1
B8: DOMICILIO:
B9: CIUDAD: | D9: AGUASCALIENTES
B11: Suma de Nota Viernes
B12: No. | C12: Viernes | D12: Producto | E12: C. Unit. | F12: Total
B13: 2 | C13: 12 | D13: LOMO DE CERDO | E13: 95 | F13: 1140
B14: 7 | C14: 13.23 | D14: PECHUGA DE POLLO DESHUESADA | E14: 150 | F14: 1984.5
B15: 8 | C15: 0.96 | D15: PECHUGA DESHUESADA EN BISTEC | E15: 150 | F15: 144
B16: 10 | C16: 18 | D16: PIERNA Y MUSLO DE POLLO SIN PIEL EN FORMA DE PISTOLA | E16: 75 | F16: 1350
B17: 12 | C17: 22.42 | D17: BISTEC DE PIERNA DE RES | E17: 160 | F17: 3587.2
B18: 17 | C18: 1.86 | D18: PULPA DE RES MOLIDA | E18: 130 | F18: 241.8
B19: 18 | C19: 2.55 | D19: HUEVO ENTERO | E19: 38 | F19: 96.9
B20: 20 | C20: 7.56 | D20: JAMÓN DE PAVO | E20: 120 | F20: 907.2
B21: Total general | F21: 9451.6

Sheet 01# Saba
D1: Carniceria "La Veronica"
D3: Jesus Manuel Romo Alba R.F.C. ROAJ600629RQ5
D4: C. ALEGRIA #211 BARRIO DEL ENCINO C. P. 20240 AGUASCALIENTES, AGS.
D5: 44576 | E5: Folio No. 7292
B7: NOMBRE: | D7: H.G.Z. No. 1
B8: DOMICILIO:
B9: CIUDAD: | D9: AGUASCALIENTES
B11: Suma de Nota Sabado
B12: No. | C12: Sabado | D12: Producto | E12: C. Unit. | F12: Total
B13: 3 | C13: 14.4 | D13: PIERNA DE CERDO EN TROZO | E13: 82 | F13: 1180.8
B14: 7 | C14: 25.35 | D14: PECHUGA DE POLLO DESHUESADA | E14: 150 | F14: 3802.5
B15: 12 | C15: 0.93 | D15: BISTEC DE PIERNA DE RES | E15: 160 | F15: 148.8
B16: 15 | C16: 12 | D16: FALDA DE RES | E16: 140 | F16: 1680
B17: 16 | C17: 4.5 | D17: PULPA DE RES EN TROZO | E17: 145 | F17: 652.5
B18: 17 | C18: 1.08 | D18: PULPA DE RES MOLIDA | E18: 130 | F18: 140.4
B19: 18 | C19: 20.8 | D19: HUEVO ENTERO | E19: 38 | F19: 790.4
B20: 20 | C20: 2.58 | D20: JAMÓN DE PAVO | E20: 120 | F20: 309.6
B21: 23 | C21: 2.5 | D21: SALCHICHA DE CERDO VIENA | E21: 40 | F21: 100
B22: Total general | F22: 8805

Sheet 01# Dom
D1: Carniceria "La Veronica"
D3: Jesus Manuel Romo Alba R.F.C. ROAJ600629RQ5
D4: C. ALEGRIA #211 BARRIO DEL ENCINO C. P. 20240 AGUASCALIENTES, AGS.
D5: 44577 | E5: Folio No. 7058
B7: NOMBRE: | D7: H.G.Z. No. 1
B8: DOMICILIO:
B9: CIUDAD: | D9: AGUASCALIENTES
B11: Suma de Nota Domingo
B12: No. | C12: domingo | D12: Producto | E12: C. Unit. | F12: Total
B13: 3 | C13: 12 | D13: PIERNA DE CERDO EN TROZO | E13: 82 | F13: 984
B14: 5 | C14: 65 | D14: MERO EN FILETE CONGELADO | E14: 90 | F14: 5850
B15: 7 | C15: 3.96 | D15: PECHUGA DE POLLO DESHUESADA | E15: 150 | F15: 594
B16: 10 | C16: 21.75 | D16: PIERNA Y MUSLO DE POLLO SIN PIEL EN FORMA DE PISTOLA | E16: 75 | F16: 1631.25
B17: 15 | C17: 10 | D17: FALDA DE RES | E17: 140 | F17: 1400
B18: 17 | C18: 0.72 | D18: PULPA DE RES MOLIDA | E18: 130 | F18: 93.6
B19: 18 | C19: 2.41 | D19: HUEVO ENTERO | E19: 38 | F19: 91.58
B20: 20 | C20: 5.04 | D20: JAMÓN DE PAVO | E20: 120 | F20: 604.8
B21: 25 | C21: 0.6 | D21: TOCINO | E21: 140 | F21: 84
B22: Total general | F22: 11333.23

Sheet 01# Lun
D1: Carniceria "La Veronica"
D3: Jesus Manuel Romo Alba R.F.C. ROAJ600629RQ5
D4: C. ALEGRIA #211 BARRIO DEL ENCINO C. P. 20240 AGUASCALIENTES, AGS.
D5: 44578 | E5: Folio No. 7061
B7: NOMBRE: | D7: H.G.Z. No. 1
B8: DOMICILIO:
B9: CIUDAD: | D9: AGUASCALIENTES
B11: Suma de Nota Lunes
B12: No. | C12: Lunes | D12: Producto | E12: C. Unit. | F12: Total
B13: 2 | C13: 14.4 | D13: LOMO DE CERDO | E13: 95 | F13: 1368
B14: 7 | C14: 31.55 | D14: PECHUGA DE POLLO DESHUESADA | E14: 150 | F14: 4732.5
B15: 17 | C15: 12.12 | D15: PULPA DE RES MOLIDA | E15: 130 | F15: 1575.6
B16: 18 | C16: 5.19 | D16: HUEVO ENTERO | E16: 38 | F16: 197.22
B17: 20 | C17: 3.84 | D17: JAMÓN DE PAVO | E17: 120 | F17: 460.8
B18: Total general | F18: 8334.12

Sheet 02# Mar
D1: Carniceria "La Veronica"
D3: Jesus Manuel Romo Alba R.F.C. ROAJ600629RQ5
D4: C. ALEGRIA #211 BARRIO DEL ENCINO C. P. 20240 AGUASCALIENTES, AGS.
D5: 44572 | E5: Folio No. 9001
B7: NOMBRE: | D7: H.G.Z. No.2
B8: DOMICILIO:
B9: CIUDAD: | D9: AGUASCALIENTES
B11: Suma de Nota Martes
B12: No. | C12: Martes | D12: Producto | E12: C. Unit. | F12: Total
B13: 6 | C13: 7 | D13: PECHUGA DE POLLO DESHUESADA | E13: 150 | F13: 1050
B14: 7 | C14: 1 | D14: PECHUGA DESHUESADA EN BISTEC | E14: 150 | F14: 150
B15: 9 | C15: 15 | D15: PIERNA Y MUSLO DE POLLO SIN PIEL EN FORMA DE PISTOLA | E15: 75 | F15: 1125
B16: 15 | C16: 17 | D16: PULPA DE RES EN TROZO | E16: 145 | F16: 2465
B17: 16 | C17: 10 | D17: PULPA DE RES MOLIDA | E17: 130 | F17: 1300
B18: 17 | C18: 17 | D18: HUEVO ENTERO | E18: 38 | F18: 646
B19: 19 | C19: 8 | D19: JAMÓN DE PAVO | E19: 120 | F19: 960
B20: 23 | C20: 2 | D20: SALCHICHA DE PAVO VIENA | E20: 50 | F20: 100
B21: 24 | C21: 0.7 | D21: TOCINO | E21: 140 | F21: 98
B22: Total general | F22: 7894

Sheet 02# Mier
D1: Carniceria "La Veronica"
D3: Jesus Manuel Romo Alba R.F.C. ROAJ600629RQ5
D4: C. ALEGRIA #211 BARRIO DEL ENCINO C. P. 20240 AGUASCALIENTES, AGS.
D5: 44573 | E5: Folio No. 8371
B7: NOMBRE: | D7: H.G.Z. No.2
B8: DOMICILIO:
B9: CIUDAD: | D9: AGUASCALIENTES
B11: Suma de Nota Miercoles
B12: No. | C12: Miercoles | D12: Producto | E12: C. Unit. | F12: Total
B13: 6 | C13: 16 | D13: PECHUGA DE POLLO DESHUESADA | E13: 150 | F13: 2400
B14: 7 | C14: 3.5 | D14: PECHUGA DESHUESADA EN BISTEC | E14: 150 | F14: 525
B15: 9 | C15: 25 | D15: PIERNA Y MUSLO DE POLLO SIN PIEL EN FORMA DE PISTOLA | E15: 75 | F15: 1875
B16: 11 | C16: 13 | D16: BISTEC DE PIERNA DE RES | E16: 160 | F16: 2080
B17: 16 | C17: 1 | D17: PULPA DE RES MOLIDA | E17: 130 | F17: 130
B18: 19 | C18: 7 | D18: JAMÓN DE PAVO | E18: 120 | F18: 840
B19: Total general | F19: 7850

Sheet 02# Juev
D1: Carniceria "La Veronica"
D3: Jesus Manuel Romo Alba R.F.C. ROAJ600629RQ5
D4: C. ALEGRIA #211 BARRIO DEL ENCINO C. P. 20240 AGUASCALIENTES, AGS.
D5: 44574 | E5: Folio No. 8381
B7: NOMBRE: | D7: H.G.Z. No.2
B8: DOMICILIO:
B9: CIUDAD: | D9: AGUASCALIENTES
B11: Suma de Nota Jueves
B12: No. | C12: Jueves | D12: Producto | E12: C. Unit. | F12: Total
B13: 3 | C13: 17 | D13: PIERNA DE CERDO EN TROZO | E13: 82 | F13: 1394
B14: 6 | C14: 1.5 | D14: PECHUGA DE POLLO DESHUESADA | E14: 150 | F14: 225
B15: 7 | C15: 9 | D15: PECHUGA DESHUESADA EN BISTEC | E15: 150 | F15: 1350
B16: 11 | C16: 8 | D16: BISTEC DE PIERNA DE RES | E16: 160 | F16: 1280
B17: 16 | C17: 7.5 | D17: PULPA DE RES MOLIDA | E17: 130 | F17: 975
B18: 17 | C18: 20 | D18: HUEVO ENTERO | E18: 38 | F18: 760
B19: 19 | C19: 0.5 | D19: JAMÓN DE PAVO | E19: 120 | F19: 60
B20: 22 | C20: 2.5 | D20: SALCHICHA DE CERDO VIENA | E20: 40 | F20: 100
B21: 23 | C21: 7 | D21: SALCHICHA DE PAVO VIENA | E21: 50 | F21: 350
B22: 24 | C22: 0.8 | D22: TOCINO | E22: 140 | F22: 112
B23: Total general | F23: 6606

Sheet 02# Viern
D1: Carniceria "La Veronica"
D3: Jesus Manuel Romo Alba R.F.C. ROAJ600629RQ5
D4: C. ALEGRIA #211 BARRIO DEL ENCINO C. P. 20240 AGUASCALIENTES, AGS.
D5: 44575 | E5: Folio No. 8001
B7: NOMBRE: | D7: H.G.Z. No.2
B8: DOMICILIO:
B9: CIUDAD: | D9: AGUASCALIENTES
B11: Suma de Nota Viernes
B12: No. | C12: Viernes | D12: Producto | E12: C. Unit. | F12: Total
B13: 2 | C13: 10 | D13: LOMO DE CERDO | E13: 95 | F13: 950
B14: 6 | C14: 13 | D14: PECHUGA DE POLLO DESHUESADA | E14: 150 | F14: 1950
B15: 7 | C15: 1 | D15: PECHUGA DESHUESADA EN BISTEC | E15: 150 | F15: 150
B16: 9 | C16: 21 | D16: PIERNA Y MUSLO DE POLLO SIN PIEL EN FORMA DE PISTOLA | E16: 75 | F16: 1575
B17: 11 | C17: 21 | D17: BISTEC DE PIERNA DE RES | E17: 160 | F17: 3360
B18: 16 | C18: 1.5 | D18: PULPA DE RES MOLIDA | E18: 130 | F18: 195
B19: 17 | C19: 4.5 | D19: HUEVO ENTERO | E19: 38 | F19: 171
B20: 19 | C20: 5 | D20: JAMÓN DE PAVO | E20: 120 | F20: 600
B21: Total general | F21: 8951

Sheet 02# Saba
D1: Carniceria "La Veronica"
D3: Jesus Manuel Romo Alba R.F.C. ROAJ600629RQ5
D4: C. ALEGRIA #211 BARRIO DEL ENCINO C. P. 20240 AGUASCALIENTES, AGS.
D5: 44576 | E5: Folio No. 7293
B7: NOMBRE: | D7: H.G.Z. No.2
B8: DOMICILIO:
B9: CIUDAD: | D9: AGUASCALIENTES
B11: Suma de Nota Sabado
B12: No. | C12: Sabado | D12: Producto | E12: C. Unit. | F12: Total
B13: 2 | C13: 17 | D13: LOMO DE CERDO | E13: 95 | F13: 1615
B14: 6 | C14: 22 | D14: PECHUGA DE POLLO DESHUESADA | E14: 150 | F14: 3300
B15: 11 | C15: 11 | D15: BISTEC DE PIERNA DE RES | E15: 160 | F15: 1760
B16: 15 | C16: 6 | D16: PULPA DE RES EN TROZO | E16: 145 | F16: 870
B17: 16 | C17: 1 | D17: PULPA DE RES MOLIDA | E17: 130 | F17: 130
B18: 17 | C18: 21 | D18: HUEVO ENTERO | E18: 38 | F18: 798
B19: 19 | C19: 2 | D19: JAMÓN DE PAVO | E19: 120 | F19: 240
B20: 22 | C20: 2.5 | D20: SALCHICHA DE CERDO VIENA | E20: 40 | F20: 100
B21: Total general | F21: 8813

Sheet 02# Dom
D1: Carniceria "La Veronica"
D3: Jesus Manuel Romo Alba R.F.C. ROAJ600629RQ5
D4: C. ALEGRIA #211 BARRIO DEL ENCINO C. P. 20240 AGUASCALIENTES, AGS.
D5: 44577 | E5: Folio No. 7059
B7: NOMBRE: | D7: H.G.Z. No.2
B8: DOMICILIO:
B9: CIUDAD: | D9: AGUASCALIENTES
B11: Suma de Nota Domingo
B12: No. | C12: domingo | D12: Producto | E12: C. Unit. | F12: Total
B13: 5 | C13: 33 | D13: MERO EN FILETE CONGELADO | E13: 90 | F13: 2970
B14: 6 | C14: 2.5 | D14: PECHUGA DE POLLO DESHUESADA | E14: 150 | F14: 375
B15: 9 | C15: 13 | D15: PIERNA Y MUSLO DE POLLO SIN PIEL EN FORMA DE PISTOLA | E15: 75 | F15: 975
B16: 15 | C16: 7 | D16: PULPA DE RES EN TROZO | E16: 145 | F16: 1015
B17: 16 | C17: 1 | D17: PULPA DE RES MOLIDA | E17: 130 | F17: 130
B18: 17 | C18: 11 | D18: HUEVO ENTERO | E18: 38 | F18: 418
B19: 19 | C19: 5 | D19: JAMÓN DE PAVO | E19: 120 | F19: 600
B20: 24 | C20: 0.7 | D20: TOCINO | E20: 140 | F20: 98
B21: Total general | F21: 6581

Sheet 02# Lun
D1: Carniceria "La Veronica"
D3: Jesus Manuel Romo Alba R.F.C. ROAJ600629RQ5
D4: C. ALEGRIA #211 BARRIO DEL ENCINO C. P. 20240 AGUASCALIENTES, AGS.
D5: 44578 | E5: Folio No. 7062
B7: NOMBRE: | D7: H.G.Z. No.2
B8: DOMICILIO:
B9: CIUDAD: | D9: AGUASCALIENTES
B11: Suma de Nota Lunes
B12: No. | C12: Lunes | D12: Producto | E12: C. Unit. | F12: Total
B13: 2 | C13: 17 | D13: LOMO DE CERDO | E13: 95 | F13: 1615
B14: 6 | C14: 28 | D14: PECHUGA DE POLLO DESHUESADA | E14: 150 | F14: 4200
B15: 16 | C15: 10 | D15: PULPA DE RES MOLIDA | E15: 130 | F15: 1300
B16: 17 | C16: 4 | D16: HUEVO ENTERO | E16: 38 | F16: 152
B17: 19 | C17: 9 | D17: JAMÓN DE PAVO | E17: 120 | F17: 1080
B18: Total general | F18: 8347

Sheet 03# Mar
D1: Carniceria "La Veronica"
D3: Jesus Manuel Romo Alba R.F.C. ROAJ600629RQ5
D4: C. ALEGRIA #211 BARRIO DEL ENCINO C. P. 20240 AGUASCALIENTES, AGS.
D5: 44572 | E5: Folio No. 9002
B7: NOMBRE: | D7: H.G.Z. No.3
B8: DOMICILIO:
B9: CIUDAD: | D9: AGUASCALIENTES
B11: Suma de Nota Martes
B12: No. | C12: Martes | D12: Producto | E12: C. Unit. | F12: Total
B13: 6 | C13: 8.15 | D13: PECHUGA DE POLLO DESHUESADA | E13: 150 | F13: 1222.5
B14: 7 | C14: 1.35 | D14: PECHUGA DESHUESADA EN BISTEC | E14: 150 | F14: 202.5
B15: 9 | C15: 12.45 | D15: PIERNA Y MUSLO DE POLLO SIN PIEL EN FORMA DE PISTOLA | E15: 75 | F15: 933.75
B16: 15 | C16: 9 | D16: PULPA DE RES EN TROZO | E16: 145 | F16: 1305
B17: 16 | C17: 5.85 | D17: PULPA DE RES MOLIDA | E17: 130 | F17: 760.5
B18: 17 | C18: 14 | D18: HUEVO ENTERO | E18: 38 | F18: 532
B19: 18 | C19: 3.6 | D19: JAMÓN DE CERDO FINO CON 16% DE PROTEÍNA | E19: 180 | F19: 648
B20: 19 | C20: 0.9 | D20: JAMÓN DE PAVO | E20: 120 | F20: 108
B21: 20 | C21: 0.9 | D21: JAMÓN DE PECHUGA DE PAVO | E21: 140 | F21: 126
B22: 23 | C22: 0.9 | D22: SALCHICHA DE PAVO VIENA | E22: 50 | F22: 45
B23: 24 | C23: 0.4 | D23: TOCINO | E23: 140 | F23: 56
B24: Total general | F24: 5939.25

Sheet 03# Mier
D1: Carniceria "La Veronica"
D3: Jesus Manuel Romo Alba R.F.C. ROAJ600629RQ5
D4: C. ALEGRIA #211 BARRIO DEL ENCINO C. P. 20240 AGUASCALIENTES, AGS.
D5: 44573 | E5: Folio No. 8372
B7: NOMBRE: | D7: H.G.Z. No.3
B8: DOMICILIO:
B9: CIUDAD: | D9: AGUASCALIENTES
B11: Suma de Nota Miercoles
B12: No. | C12: Miercoles | D12: Producto | E12: C. Unit. | F12: Total
B13: 6 | C13: 17.5 | D13: PECHUGA DE POLLO DESHUESADA | E13: 150 | F13: 2625
B14: 7 | C14: 2.7 | D14: PECHUGA DESHUESADA EN BISTEC | E14: 150 | F14: 405
B15: 9 | C15: 15.75 | D15: PIERNA Y MUSLO DE POLLO SIN PIEL EN FORMA DE PISTOLA | E15: 75 | F15: 1181.25
B16: 11 | C16: 9.6 | D16: BISTEC DE PIERNA DE RES | E16: 160 | F16: 1536
B17: 16 | C17: 0.97 | D17: PULPA DE RES MOLIDA | E17: 130 | F17: 126.1
B18: 17 | C18: 1 | D18: HUEVO ENTERO | E18: 38 | F18: 38
B19: 18 | C19: 3.9 | D19: JAMÓN DE CERDO FINO CON 16% DE PROTEÍNA | E19: 180 | F19: 702
B20: Total general | F20: 6613.35

Sheet 03# Juev
D1: Carniceria "La Veronica"
D3: Jesus Manuel Romo Alba R.F.C. ROAJ600629RQ5
D4: C. ALEGRIA #211 BARRIO DEL ENCINO C. P. 20240 AGUASCALIENTES, AGS.
D5: 44574 | E5: Folio No. 8382
B7: NOMBRE: | D7: H.G.Z. No.3
B8: DOMICILIO:
B9: CIUDAD: | D9: AGUASCALIENTES
B11: Suma de Nota Jueves
B12: No. | C12: Jueves | D12: Producto | E12: C. Unit. | F12: Total
B13: 3 | C13: 9 | D13: PIERNA DE CERDO EN TROZO | E13: 82 | F13: 738
B14: 6 | C14: 1.1 | D14: PECHUGA DE POLLO DESHUESADA | E14: 150 | F14: 165
B15: 7 | C15: 9.27 | D15: PECHUGA DESHUESADA EN BISTEC | E15: 150 | F15: 1390.5
B16: 11 | C16: 6 | D16: BISTEC DE PIERNA DE RES | E16: 160 | F16: 960
B17: 16 | C17: 7.5 | D17: PULPA DE RES MOLIDA | E17: 130 | F17: 975
B18: 17 | C18: 17 | D18: HUEVO ENTERO | E18: 38 | F18: 646
B19: 19 | C19: 0.21 | D19: JAMÓN DE PAVO | E19: 120 | F19: 25.2
B20: 22 | C20: 1.8 | D20: SALCHICHA DE CERDO VIENA | E20: 40 | F20: 72
B21: 23 | C21: 4.2 | D21: SALCHICHA DE PAVO VIENA | E21: 50 | F21: 210
B22: 24 | C22: 0.6 | D22: TOCINO | E22: 140 | F22: 84
B23: Total general | F23: 5265.7

Sheet 03# Viern
D1: Carniceria "La Veronica"
D3: Jesus Manuel Romo Alba R.F.C. ROAJ600629RQ5
D4: C. ALEGRIA #211 BARRIO DEL ENCINO C. P. 20240 AGUASCALIENTES, AGS.
D5: 44575 | E5: Folio No. 8002
B7: NOMBRE: | D7: H.G.Z. No.3
B8: DOMICILIO:
B9: CIUDAD: | D9: AGUASCALIENTES
B11: Suma de Nota Viernes
B12: No. | C12: Viernes | D12: Producto | E12: C. Unit. | F12: Total
B13: 2 | C13: 7.2 | D13: LOMO DE CERDO | E13: 95 | F13: 684
B14: 6 | C14: 12.3 | D14: PECHUGA DE POLLO DESHUESADA | E14: 150 | F14: 1845
B15: 7 | C15: 1.35 | D15: PECHUGA DESHUESADA EN BISTEC | E15: 150 | F15: 202.5
B16: 9 | C16: 9.75 | D16: PIERNA Y MUSLO DE POLLO SIN PIEL EN FORMA DE PISTOLA | E16: 75 | F16: 731.25
B17: 11 | C17: 14.7 | D17: BISTEC DE PIERNA DE RES | E17: 160 | F17: 2352
B18: 16 | C18: 1.4 | D18: PULPA DE RES MOLIDA | E18: 130 | F18: 182
B19: 17 | C19: 5 | D19: HUEVO ENTERO | E19: 38 | F19: 190
B20: 19 | C20: 3.6 | D20: JAMÓN DE PAVO | E20: 120 | F20: 432
B21: Total general | F21: 6618.75

Sheet 03# Saba
D1: Carniceria "La Veronica"
D3: Jesus Manuel Romo Alba R.F.C. ROAJ600629RQ5
D4: C. ALEGRIA #211 BARRIO DEL ENCINO C. P. 20240 AGUASCALIENTES, AGS.
D5: 44576 | E5: Folio No. 7294
B7: NOMBRE: | D7: H.G.Z. No.3
B8: DOMICILIO:
B9: CIUDAD: | D9: AGUASCALIENTES
B11: Suma de Nota Sabado
B12: No. | C12: Sabado | D12: Producto | E12: C. Unit. | F12: Total
B13: 2 | C13: 7.8 | D13: LOMO DE CERDO | E13: 95 | F13: 741
B14: 6 | C14: 19.1 | D14: PECHUGA DE POLLO DESHUESADA | E14: 150 | F14: 2865
B15: 11 | C15: 9 | D15: BISTEC DE PIERNA DE RES | E15: 160 | F15: 1440
B16: 15 | C16: 5.4 | D16: PULPA DE RES EN TROZO | E16: 145 | F16: 783
B17: 16 | C17: 1.02 | D17: PULPA DE RES MOLIDA | E17: 130 | F17: 132.6
B18: 17 | C18: 16 | D18: HUEVO ENTERO | E18: 38 | F18: 608
B19: 19 | C19: 1.35 | D19: JAMÓN DE PAVO | E19: 120 | F19: 162
B20: 22 | C20: 1.75 | D20: SALCHICHA DE CERDO VIENA | E20: 40 | F20: 70
B21: Total general | F21: 6801.6

Sheet 03# Dom
D1: Carniceria "La Veronica"
D3: Jesus Manuel Romo Alba R.F.C. ROAJ600629RQ5
D4: C. ALEGRIA #211 BARRIO DEL ENCINO C. P. 20240 AGUASCALIENTES, AGS.
D5: 44577 | E5: Folio No. 7060
B7: NOMBRE: | D7: H.G.Z. No.3
B8: DOMICILIO:
B9: CIUDAD: | D9: AGUASCALIENTES
B11: Suma de Nota Domingo
B12: No. | C12: domingo | D12: Producto | E12: C. Unit. | F12: Total
B13: 5 | C13: 19.5 | D13: MERO EN FILETE CONGELADO | E13: 90 | F13: 1755
B14: 6 | C14: 3.13 | D14: PECHUGA DE POLLO DESHUESADA | E14: 150 | F14: 469.5
B15: 9 | C15: 15.45 | D15: PIERNA Y MUSLO DE POLLO SIN PIEL EN FORMA DE PISTOLA | E15: 75 | F15: 1158.75
B16: 15 | C16: 5.4 | D16: PULPA DE RES EN TROZO | E16: 145 | F16: 783
B17: 16 | C17: 1.35 | D17: PULPA DE RES MOLIDA | E17: 130 | F17: 175.5
B18: 17 | C18: 9 | D18: HUEVO ENTERO | E18: 38 | F18: 342
B19: 19 | C19: 3 | D19: JAMÓN DE PAVO | E19: 120 | F19: 360
B20: 24 | C20: 0.4 | D20: TOCINO | E20: 140 | F20: 56
B21: Total general | F21: 5099.75

Sheet 03# Lun
D1: Carniceria "La Veronica"
D3: Jesus Manuel Romo Alba R.F.C. ROAJ600629RQ5
D4: C. ALEGRIA #211 BARRIO DEL ENCINO C. P. 20240 AGUASCALIENTES, AGS.
D5: 44578 | E5: Folio No. 7063
B7: NOMBRE: | D7: H.G.Z. No.3
B8: DOMICILIO:
B9: CIUDAD: | D9: AGUASCALIENTES
B11: Suma de Nota Lunes
B12: No. | C12: Lunes | D12: Producto | E12: C. Unit. | F12: Total
B13: 2 | C13: 9 | D13: LOMO DE CERDO | E13: 95 | F13: 855
B14: 6 | C14: 21.38 | D14: PECHUGA DE POLLO DESHUESADA | E14: 150 | F14: 3207
B15: 16 | C15: 9.46 | D15: PULPA DE RES MOLIDA | E15: 130 | F15: 1229.8
B16: 17 | C16: 4 | D16: HUEVO ENTERO | E16: 38 | F16: 152
B17: 18 | C17: 4.8 | D17: JAMÓN DE CERDO FINO CON 16% DE PROTEÍNA | E17: 180 | F17: 864
B18: 19 | C18: 2.7 | D18: JAMÓN DE PAVO | E18: 120 | F18: 324
B19: Total general | F19: 6631.8

Sheet Gua# Lun
D1: Carniceria "La Veronica"
D3: Jesus Manuel Romo Alba R.F.C. ROAJ600629RQ5
D4: C. ALEGRIA #211 BARRIO DEL ENCINO C. P. 20240 AGUASCALIENTES, AGS.
D5: 44571 | E5: Folio No. 9036
B7: NOMBRE: | D7: GUARDERIA ORDINARIA G-0001
B8: DOMICILIO:
B9: CIUDAD: | D9: AGUASCALIENTES
B10: Suma de Nota Lunes
B11: No. | C11: Lunes | D11: Producto | E11: PRECIO VENTA | F11: Total
B12: 6 | C12: 10 | D12: PECHUGA DE POLLO DESHUESADA | E12: 150 | F12: 1500
B13: 15 | C13: 6 | D13: PULPA DE RES EN TROZO | E13: 145 | F13: 870
B14: 16 | C14: 4 | D14: PULPA DE RES MOLIDA | E14: 130 | F14: 520
B15: 17 | C15: 12 | D15: HUEVO ENTERO | E15: 38 | F15: 456
B16: Total general | F16: 3346

Sheet Gua# Mar
D1: Carniceria "La Veronica"
D3: Jesus Manuel Romo Alba R.F.C. ROAJ600629RQ5
D4: C. ALEGRIA #211 BARRIO DEL ENCINO C. P. 20240 AGUASCALIENTES, AGS.
D5: 44572 | E5: Folio No. 9043
B7: NOMBRE: | D7: GUARDERIA ORDINARIA G-0001
B8: DOMICILIO:
B9: CIUDAD: | D9: AGUASCALIENTES
B10: Suma de Nota Martes
B11: No. | C11: Martes | D11: Producto | E11: PRECIO VENTA | F11: Total
B12: 2 | C12: 6 | D12: LOMO DE CERDO | E12: 95 | F12: 570
B13: 6 | C13: 10 | D13: PECHUGA DE POLLO DESHUESADA | E13: 150 | F13: 1500
B14: 16 | C14: 2.5 | D14: PULPA DE RES MOLIDA | E14: 130 | F14: 325
B15: 17 | C15: 5 | D15: HUEVO ENTERO | E15: 38 | F15: 190
B16: Total general | F16: 2585

Sheet Gua# Mie
D1: Carniceria "La Veronica"
D3: Jesus Manuel Romo Alba R.F.C. ROAJ600629RQ5
D4: C. ALEGRIA #211 BARRIO DEL ENCINO C. P. 20240 AGUASCALIENTES, AGS.
D5: 44573 | E5: Folio No. 8180
B7: NOMBRE: | D7: GUARDERIA ORDINARIA G-0001
B8: DOMICILIO:
B9: CIUDAD: | D9: AGUASCALIENTES
B10: Suma de Nota Miercoles
B11: No. | C11: Miercoles | D11: Producto | E11: PRECIO VENTA | F11: Total
B12: 6 | C12: 2.5 | D12: PECHUGA DE POLLO DESHUESADA | E12: 150 | F12: 375
B13: 16 | C13: 1.5 | D13: PULPA DE RES MOLIDA | E13: 130 | F13: 195
B14: 17 | C14: 4 | D14: HUEVO ENTERO | E14: 38 | F14: 152
B15: Total general | F15: 722

Sheet Gua# Juev
D1: Carniceria "La Veronica"
D3: Jesus Manuel Romo Alba R.F.C. ROAJ600629RQ5
D4: C. ALEGRIA #211 BARRIO DEL ENCINO C. P. 20240 AGUASCALIENTES, AGS.
D5: 44574 | E5: Folio No. 8383
B7: NOMBRE: | D7: GUARDERIA ORDINARIA G-0001
B8: DOMICILIO:
B9: CIUDAD: | D9: AGUASCALIENTES
B10: Suma de Nota Jueves
B11: No. | C11: Jueves | D11: Producto | E11: PRECIO VENTA | F11: Total
B12: 6 | C12: 5 | D12: PECHUGA DE POLLO DESHUESADA | E12: 150 | F12: 750
B13: 11 | C13: 4 | D13: BISTEC DE PIERNA DE RES | E13: 160 | F13: 640
B14: 17 | C14: 5 | D14: HUEVO ENTERO | E14: 38 | F14: 190
B15: Total general | F15: 1580

Sheet Gua# Vier
D1: Carniceria "La Veronica"
D3: Jesus Manuel Romo Alba R.F.C. ROAJ600629RQ5
D4: C. ALEGRIA #211 BARRIO DEL ENCINO C. P. 20240 AGUASCALIENTES, AGS.
D5: 44575 | E5: Folio No. 8003
B7: NOMBRE: | D7: GUARDERIA ORDINARIA G-0001
B8: DOMICILIO:
B9: CIUDAD: | D9: AGUASCALIENTES
B10: Suma de Nota Viernes
B11: No. | C11: Viernes | D11: Producto | E11: PRECIO VENTA | F11: Total
B12: 16 | C12: 5 | D12: PULPA DE RES MOLIDA | E12: 130 | F12: 650
B13: 17 | C13: 5 | D13: HUEVO ENTERO | E13: 38 | F13: 190
B14: Total general | F14: 840

Sheet IMSS 1
C1: =('ORDENES '!L1) -> 11-17 enero
J2: CLINICA IMMS 1
A3: No. | B3: Producto | C3: Martes | D3: Miercoles | E3: Jueves | F3: Viernes | G3: Sabado | H3: domingo | I3: Lunes | J3: Total / semana | K3: Importe Martes | L3: Nota Martes | M3: Imp Miercoles | N3: Nota Miercoles | O3: Imp. Jueves | P3: Nota Jueves | Q3: Imp. Viernes | R3: Nota Viernes | S3: Imp. Sabado | T3: Nota Sabado | U3: Imp. Domingo | V3: Nota Domingo | W3: Imp. Lunes | X3: Nota Lunes | Y3: PRECIO COSTO | Z3: PRECIO VENTA | AA3: Total Compra | AB3: Total Venta | AC3: Utilidad
A4: 1 | B4: =(PRECIOS!B4) -> CHULETA DE CERDO | C4: =SUM('ORDENES '!D3) -> 0 | D4: =SUM('ORDENES '!E3) -> 0 | E4: =SUM('ORDENES '!F3) -> 0 | F4: =SUM('ORDENES '!G3) -> 0 | G4: =SUM('ORDENES '!H3) -> 0 | H4: =SUM('ORDENES '!I3) -> 0 | I4: =SUM('ORDENES '!J3) -> 0 | J4: =SUM(C4:I4) -> 0 | K4: =SUM(C4*Y4) -> 0 | L4: =SUM(C4*Z4) -> 0 | M4: =SUM(D4*Y4) -> 0 | N4: =SUM(D4*Z4) -> 0 | O4: =SUM(E4*Y4) -> 0 | P4: =SUM(E4*Z4) -> 0 | Q4: =SUM(F4*Y4) -> 0 | R4: =SUM(F4*Z4) -> 0 | S4: =SUM(G4*Y4) -> 0 | T4: =SUM(G4*Z4) -> 0 | U4: =SUM(H4*Y4) -> 0 | V4: =SUM(H4*Z4) -> 0 | W4: =SUM(I4*Y4) -> 0 | X4: =SUM(I4*Z4) -> 0 | Y4: =SUM(PRECIOS!C4) -> 89 | Z4: =SUM(PRECIOS!D4) -> 89 | AA4: =Y4*J4 -> 0 | AB4: =Z4*J4 -> 0 | AC4: =AB4-AA4 -> 0
A5: 2 | B5: =(PRECIOS!B5) -> LOMO DE CERDO | C5: =SUM('ORDENES '!D4) -> 0 | D5: =SUM('ORDENES '!E4) -> 0 | E5: =SUM('ORDENES '!F4) -> 0 | F5: =SUM('ORDENES '!G4) -> 12 | G5: =SUM('ORDENES '!H4) -> 0 | H5: =SUM('ORDENES '!I4) -> 0 | I5: =SUM('ORDENES '!J4) -> 14.4 | J5: =SUM(C5:I5) -> 26.4 | K5: =SUM(C5*Y5) -> 0 | L5: =SUM(C5*Z5) -> 0 | M5: =SUM(D5*Y5) -> 0 | N5: =SUM(D5*Z5) -> 0 | O5: =SUM(E5*Y5) -> 0 | P5: =SUM(E5*Z5) -> 0 | Q5: =SUM(F5*Y5) -> 600 | R5: =SUM(F5*Z5) -> 1140 | S5: =SUM(G5*Y5) -> 0 | T5: =SUM(G5*Z5) -> 0 | U5: =SUM(H5*Y5) -> 0 | V5: =SUM(H5*Z5) -> 0 | W5: =SUM(I5*Y5) -> 720 | X5: =SUM(I5*Z5) -> 1368 | Y5: =SUM(PRECIOS!C5) -> 50 | Z5: =SUM(PRECIOS!D5) -> 95 | AA5: =Y5*J5 -> 1320 | AB5: =Z5*J5 -> 2508 | AC5: =AB5-AA5 -> 1188
A6: 3 | B6: =(PRECIOS!B6) -> PIERNA DE CERDO EN TROZO | C6: =SUM('ORDENES '!D5) -> 0 | D6: =SUM('ORDENES '!E5) -> 0 | E6: =SUM('ORDENES '!F5) -> 14.4 | F6: =SUM('ORDENES '!G5) -> 0 | G6: =SUM('ORDENES '!H5) -> 14.4 | H6: =SUM('ORDENES '!I5) -> 12 | I6: =SUM('ORDENES '!J5) -> 0 | J6: =SUM(C6:I6) -> 40.8 | K6: =SUM(C6*Y6) -> 0 | L6: =SUM(C6*Z6) -> 0 | M6: =SUM(D6*Y6) -> 0 | N6: =SUM(D6*Z6) -> 0 | O6: =SUM(E6*Y6) -> 921.6 | P6: =SUM(E6*Z6) -> 1180.8 | Q6: =SUM(F6*Y6) -> 0 | R6: =SUM(F6*Z6) -> 0 | S6: =SUM(G6*Y6) -> 921.6 | T6: =SUM(G6*Z6) -> 1180.8 | U6: =SUM(H6*Y6) -> 768 | V6: =SUM(H6*Z6) -> 984 | W6: =SUM(I6*Y6) -> 0 | X6: =SUM(I6*Z6) -> 0 | Y6: =SUM(PRECIOS!C6) -> 64 | Z6: =SUM(PRECIOS!D6) -> 82 | AA6: =Y6*J6 -> 2611.2 | AB6: =Z6*J6 -> 3345.6 | AC6: =AB6-AA6 -> 734.4
A7: 4 | B7: =(PRECIOS!B7) -> PIERNA DE CERDO MOLIDA | C7: =SUM('ORDENES '!D6) -> 0 | D7: =SUM('ORDENES '!E6) -> 0 | E7: =SUM('ORDENES '!F6) -> 0 | F7: =SUM('ORDENES '!G6) -> 0 | G7: =SUM('ORDENES '!H6) -> 0 | H7: =SUM('ORDENES '!I6) -> 0 | I7: =SUM('ORDENES '!J6) -> 0 | J7: =SUM(C7:I7) -> 0 | K7: =SUM(C7*Y7) -> 0 | L7: =SUM(C7*Z7) -> 0 | M7: =SUM(D7*Y7) -> 0 | N7: =SUM(D7*Z7) -> 0 | O7: =SUM(E7*Y7) -> 0 | P7: =SUM(E7*Z7) -> 0 | Q7: =SUM(F7*Y7) -> 0 | R7: =SUM(F7*Z7) -> 0 | S7: =SUM(G7*Y7) -> 0 | T7: =SUM(G7*Z7) -> 0 | U7: =SUM(H7*Y7) -> 0 | V7: =SUM(H7*Z7) -> 0 | W7: =SUM(I7*Y7) -> 0 | X7: =SUM(I7*Z7) -> 0 | Y7: =SUM(PRECIOS!C7) -> 50 | Z7: =SUM(PRECIOS!D7) -> 60 | AA7: =Y7*J7 -> 0 | AB7: =Z7*J7 -> 0 | AC7: =AB7-AA7 -> 0
A8: 5 | B8: =(PRECIOS!B8) -> MERO EN FILETE CONGELADO | C8: =SUM('ORDENES '!D7) -> 0 | D8: =SUM('ORDENES '!E7) -> 0 | E8: =SUM('ORDENES '!F7) -> 0 | F8: =SUM('ORDENES '!G7) -> 0 | G8: =SUM('ORDENES '!H7) -> 0 | H8: =SUM('ORDENES '!I7) -> 65 | I8: =SUM('ORDENES '!J7) -> 0 | J8: =SUM(C8:I8) -> 65 | K8: =SUM(C8*Y8) -> 0 | L8: =SUM(C8*Z8) -> 0 | M8: =SUM(D8*Y8) -> 0 | N8: =SUM(D8*Z8) -> 0 | O8: =SUM(E8*Y8) -> 0 | P8: =SUM(E8*Z8) -> 0 | Q8: =SUM(F8*Y8) -> 0 | R8: =SUM(F8*Z8) -> 0 | S8: =SUM(G8*Y8) -> 0 | T8: =SUM(G8*Z8) -> 0 | U8: =SUM(H8*Y8) -> 3698.5 | V8: =SUM(H8*Z8) -> 5850 | W8: =SUM(I8*Y8) -> 0 | X8: =SUM(I8*Z8) -> 0 | Y8: =SUM(PRECIOS!C8) -> 56.9 | Z8: =SUM(PRECIOS!D8) -> 90 | AA8: =Y8*J8 -> 3698.5 | AB8: =Z8*J8 -> 5850 | AC8: =AB8-AA8 -> 2151.5
A9: 6 | B9: =(PRECIOS!B9) -> PECHUGA DE POLLO | C9: =SUM('ORDENES '!D8) -> 0 | D9: =SUM('ORDENES '!E8) -> 0 | E9: =SUM('ORDENES '!F8) -> 0 | F9: =SUM('ORDENES '!G8) -> 0 | G9: =SUM('ORDENES '!H8) -> 0 | H9: =SUM('ORDENES '!I8) -> 0 | I9: =SUM('ORDENES '!J8) -> 0 | J9: =SUM(C9:I9) -> 0 | K9: =SUM(C9*Y9) -> 0 | L9: =SUM(C9*Z9) -> 0 | M9: =SUM(D9*Y9) -> 0 | N9: =SUM(D9*Z9) -> 0 | O9: =SUM(E9*Y9) -> 0 | P9: =SUM(E9*Z9) -> 0 | Q9: =SUM(F9*Y9) -> 0 | R9: =SUM(F9*Z9) -> 0 | S9: =SUM(G9*Y9) -> 0 | T9: =SUM(G9*Z9) -> 0 | U9: =SUM(H9*Y9) -> 0 | V9: =SUM(H9*Z9) -> 0 | W9: =SUM(I9*Y9) -> 0 | X9: =SUM(I9*Z9) -> 0 | Y9: =SUM(PRECIOS!C9) -> 0 | Z9: =SUM(PRECIOS!D9) -> 98 | AA9: =Y9*J9 -> 0 | AB9: =Z9*J9 -> 0 | AC9: =AB9-AA9 -> 0
A10: 7 | B10: =(PRECIOS!B10) -> PECHUGA DE POLLO DESHUESADA | C10: =SUM('ORDENES '!D9) -> 11.48 | D10: =SUM('ORDENES '!E9) -> 20.08 | E10: =SUM('ORDENES '!F9) -> 0.72 | F10: =SUM('ORDENES '!G9) -> 13.23 | G10: =SUM('ORDENES '!H9) -> 25.35 | H10: =SUM('ORDENES '!I9) -> 3.96 | I10: =SUM('ORDENES '!J9) -> 31.55 | J10: =SUM(C10:I10) -> 106.37 | K10: =SUM(C10*Y10) -> 847.224 | L10: =SUM(C10*Z10) -> 1722 | M10: =SUM(D10*Y10) -> 1481.904 | N10: =SUM(D10*Z10) -> 3012 | O10: =SUM(E10*Y10) -> 53.136 | P10: =SUM(E10*Z10) -> 108 | Q10: =SUM(F10*Y10) -> 976.374 | R10: =SUM(F10*Z10) -> 1984.5 | S10: =SUM(G10*Y10) -> 1870.83 | T10: =SUM(G10*Z10) -> 3802.5 | U10: =SUM(H10*Y10) -> 292.248 | V10: =SUM(H10*Z10) -> 594 | W10: =SUM(I10*Y10) -> 2328.39 | X10: =SUM(I10*Z10) -> 4732.5 | Y10: =SUM(PRECIOS!C10) -> 73.8 | Z10: =SUM(PRECIOS!D10) -> 150 | AA10: =Y10*J10 -> 7850.106 | AB10: =Z10*J10 -> 15955.5 | AC10: =AB10-AA10 -> 8105.394
A11: 8 | B11: =(PRECIOS!B11) -> PECHUGA DESHUESADA EN BISTEC | C11: =SUM('ORDENES '!D10) -> 0.96 | D11: =SUM('ORDENES '!E10) -> 3.6 | E11: =SUM('ORDENES '!F10) -> 17.4 | F11: =SUM('ORDENES '!G10) -> 0.96 | G11: =SUM('ORDENES '!H10) -> 0 | H11: =SUM('ORDENES '!I10) -> 0 | I11: =SUM('ORDENES '!J10) -> 0 | J11: =SUM(C11:I11) -> 22.92 | K11: =SUM(C11*Y11) -> 70.848 | L11: =SUM(C11*Z11) -> 144 | M11: =SUM(D11*Y11) -> 265.68 | N11: =SUM(D11*Z11) -> 540 | O11: =SUM(E11*Y11) -> 1284.12 | P11: =SUM(E11*Z11) -> 2610 | Q11: =SUM(F11*Y11) -> 70.848 | R11: =SUM(F11*Z11) -> 144 | S11: =SUM(G11*Y11) -> 0 | T11: =SUM(G11*Z11) -> 0 | U11: =SUM(H11*Y11) -> 0 | V11: =SUM(H11*Z11) -> 0 | W11: =SUM(I11*Y11) -> 0 | X11: =SUM(I11*Z11) -> 0 | Y11: =SUM(PRECIOS!C11) -> 73.8 | Z11: =SUM(PRECIOS!D11) -> 150 | AA11: =Y11*J11 -> 1691.496 | AB11: =Z11*J11 -> 3438 | AC11: =AB11-AA11 -> 1746.504
A12: 9 | B12: =(PRECIOS!B12) -> PECHUGA DE POLLO MÓLIDA | C12: =SUM('ORDENES '!D11) -> 0 | D12: =SUM('ORDENES '!E11) -> 0 | E12: =SUM('ORDENES '!F11) -> 0 | F12: =SUM('ORDENES '!G11) -> 0 | G12: =SUM('ORDENES '!H11) -> 0 | H12: =SUM('ORDENES '!I11) -> 0 | I12: =SUM('ORDENES '!J11) -> 0 | J12: =SUM(C12:I12) -> 0 | K12: =SUM(C12*Y12) -> 0 | L12: =SUM(C12*Z12) -> 0 | M12: =SUM(D12*Y12) -> 0 | N12: =SUM(D12*Z12) -> 0 | O12: =SUM(E12*Y12) -> 0 | P12: =SUM(E12*Z12) -> 0 | Q12: =SUM(F12*Y12) -> 0 | R12: =SUM(F12*Z12) -> 0 | S12: =SUM(G12*Y12) -> 0 | T12: =SUM(G12*Z12) -> 0 | U12: =SUM(H12*Y12) -> 0 | V12: =SUM(H12*Z12) -> 0 | W12: =SUM(I12*Y12) -> 0 | X12: =SUM(I12*Z12) -> 0 | Y12: =SUM(PRECIOS!C12) -> 55 | Z12: =SUM(PRECIOS!D12) -> 75 | AA12: =Y12*J12 -> 0 | AB12: =Z12*J12 -> 0 | AC12: =AB12-AA12 -> 0
A13: 10 | B13: =(PRECIOS!B13) -> PIERNA Y MUSLO DE POLLO SIN PIEL EN FORMA DE PISTOLA | C13: =SUM('ORDENES '!D12) -> 19.8 | D13: =SUM('ORDENES '!E12) -> 21.15 | E13: =SUM('ORDENES '!F12) -> 0 | F13: =SUM('ORDENES '!G12) -> 18 | G13: =SUM('ORDENES '!H12) -> 0 | H13: =SUM('ORDENES '!I12) -> 21.75 | I13: =SUM('ORDENES '!J12) -> 0 | J13: =SUM(C13:I13) -> 80.7 | K13: =SUM(C13*Y13) -> 708.84 | L13: =SUM(C13*Z13) -> 1287 | M13: =SUM(D13*Y13) -> 757.17 | N13: =SUM(D13*Z13) -> 1374.75 | O13: =SUM(E13*Y13) -> 0 | P13: =SUM(E13*Z13) -> 0 | Q13: =SUM(F13*Y13) -> 644.4 | R13: =SUM(F13*Z13) -> 1170 | S13: =SUM(G13*Y13) -> 0 | T13: =SUM(G13*Z13) -> 0 | U13: =SUM(H13*Y13) -> 778.65 | V13: =SUM(H13*Z13) -> 1413.75 | W13: =SUM(I13*Y13) -> 0 | X13: =SUM(I13*Z13) -> 0 | Y13: =SUM(PRECIOS!C13) -> 35.8 | Z13: =SUM(PRECIOS!D13) -> 65 | AA13: =Y13*J13 -> 2889.06 | AB13: =Z13*J13 -> 5245.5 | AC13: =AB13-AA13 -> 2356.44
A14: 11 | B14: =(PRECIOS!B14) -> POLLO ENTERO | C14: =SUM('ORDENES '!D13) -> 0 | D14: =SUM('ORDENES '!E13) -> 0 | E14: =SUM('ORDENES '!F13) -> 0 | F14: =SUM('ORDENES '!G13) -> 0 | G14: =SUM('ORDENES '!H13) -> 0 | H14: =SUM('ORDENES '!I13) -> 0 | I14: =SUM('ORDENES '!J13) -> 0 | J14: =SUM(C14:I14) -> 0 | K14: =SUM(C14*Y14) -> 0 | L14: =SUM(C14*Z14) -> 0 | M14: =SUM(D14*Y14) -> 0 | N14: =SUM(D14*Z14) -> 0 | O14: =SUM(E14*Y14) -> 0 | P14: =SUM(E14*Z14) -> 0 | Q14: =SUM(F14*Y14) -> 0 | R14: =SUM(F14*Z14) -> 0 | S14: =SUM(G14*Y14) -> 0 | T14: =SUM(G14*Z14) -> 0 | U14: =SUM(H14*Y14) -> 0 | V14: =SUM(H14*Z14) -> 0 | W14: =SUM(I14*Y14) -> 0 | X14: =SUM(I14*Z14) -> 0 | Y14: =SUM(PRECIOS!C14) -> 50 | Z14: =SUM(PRECIOS!D14) -> 50 | AA14: =Y14*J14 -> 0 | AB14: =Z14*J14 -> 0 | AC14: =AB14-AA14 -> 0
A15: 12 | B15: =(PRECIOS!B15) -> BISTEC DE PIERNA DE RES | C15: =SUM('ORDENES '!D14) -> 0 | D15: =SUM('ORDENES '!E14) -> 12 | E15: =SUM('ORDENES '!F14) -> 10 | F15: =SUM('ORDENES '!G14) -> 22.42 | G15: =SUM('ORDENES '!H14) -> 0.93 | H15: =SUM('ORDENES '!I14) -> 0 | I15: =SUM('ORDENES '!J14) -> 0 | J15: =SUM(C15:I15) -> 45.35 | K15: =SUM(C15*Y15) -> 0 | L15: =SUM(C15*Z15) -> 0 | M15: =SUM(D15*Y15) -> 1680 | N15: =SUM(D15*Z15) -> 1920 | O15: =SUM(E15*Y15) -> 1400 | P15: =SUM(E15*Z15) -> 1600 | Q15: =SUM(F15*Y15) -> 3138.8 | R15: =SUM(F15*Z15) -> 3587.2 | S15: =SUM(G15*Y15) -> 130.2 | T15: =SUM(G15*Z15) -> 148.8 | U15: =SUM(H15*Y15) -> 0 | V15: =SUM(H15*Z15) -> 0 | W15: =SUM(I15*Y15) -> 0 | X15: =SUM(I15*Z15) -> 0 | Y15: =SUM(PRECIOS!C15) -> 140 | Z15: =SUM(PRECIOS!D15) -> 160 | AA15: =Y15*J15 -> 6349 | AB15: =Z15*J15 -> 7256 | AC15: =AB15-AA15 -> 907
... A28: 25 | B28: =(PRECIOS!B28) -> TOCINO | C28: =SUM('ORDENES '!D27) -> 0.55 | D28: =SUM('ORDENES '!E27) -> 0 | E28: =SUM('ORDENES '!F27) -> 1 | F28: =SUM('ORDENES '!G27) -> 0 | G28: =SUM('ORDENES '!H27) -> 0 | H28: =SUM('ORDENES '!I27) -> 0.6 | I28: =SUM('ORDENES '!J27) -> 0 | J28: =SUM(C28:I28) -> 2.15 | K28: =SUM(C28*Y28) -> 49.5 | L28: =SUM(C28*Z28) -> 77 | M28: =SUM(D28*Y28) -> 0 | N28: =SUM(D28*Z28) -> 0 | O28: =SUM(E28*Y28) -> 90 | P28: =SUM(E28*Z28) -> 140 | Q28: =SUM(F28*Y28) -> 0 | R28: =SUM(F28*Z28) -> 0 | S28: =SUM(G28*Y28) -> 0 | T28: =SUM(G28*Z28) -> 0 | U28: =SUM(H28*Y28) -> 54 | V28: =SUM(H28*Z28) -> 84 | W28: =SUM(I28*Y28) -> 0 | X28: =SUM(I28*Z28) -> 0 | Y28: =SUM(PRECIOS!C28) -> 90 | Z28: =SUM(PRECIOS!D28) -> 140 | AA28: =Y28*J28 -> 193.5 | AB28: =Z28*J28 -> 301 | AC28: =AB28-AA28 -> 107.5
J29: =SUM(J4:J28) -> 574.71 | K29: =SUM(K4:K28) -> 4828.415 | L29: =SUM(L4:L28) -> 8528.42 | M29: =SUM(M4:M28) -> 4290.546 | N29: =SUM(N4:N28) -> 7023.83 | O29: =SUM(O4:O28) -> 5488.406 | P29: =SUM(P4:P28) -> 8334.4 | Q29: =SUM(Q4:Q28) -> 6091.607 | ... X29: =SUM(X4:X28) -> 8334.12 | AA29: =SUM(K29,M29,O29,Q29,S29,U29,W29) -> 36996.272 | AB29: =SUM(L29,N29,P29,R29,T29,V29,X29) -> 61413.1 | AC29: =SUM(AB29-AA29) -> 24416.828

Sheet IMSS 2
C1: =('ORDENES '!L1) -> 11-17 enero
K2: CLINICA IMMS 2
A3: No. | B3: Producto | C3: Martes | D3: Miercoles | E3: Jueves | F3: Viernes | G3: Sabado | H3: domingo | I3: Lunes | J3: Total / semana | K3: Importe Martes | L3: Nota Martes | M3: Imp Miercoles | N3: Nota Miercoles | O3: Imp. Jueves | P3: Nota Jueves | Q3: Imp. Viernes | R3: Nota Viernes | S3: Imp. Sabado | T3: Nota Sabado | U3: Imp. Domingo | V3: Nota Domingo | W3: Imp. Lunes | X3: Nota Lunes | Y3: PRECIO COSTO | Z3: PRECIO VENTA | AA3: Total Compra | AB3: Total Venta | AC3: Utilidad
A4: 1 | B4: =(PRECIOS!B4) -> CHULETA DE CERDO | C4: =SUM('ORDENES '!O3) -> 0 | D4: =SUM('ORDENES '!P3) -> 0 | E4: =SUM('ORDENES '!Q3) -> 0 | F4: =SUM('ORDENES '!R3) -> 0 | G4: =SUM('ORDENES '!S3) -> 0 | H4: =SUM('ORDENES '!T3) -> 0 | I4: =SUM('ORDENES '!U3) -> 0 | J4: =SUM(C4:I4) -> 0 | K4: =SUM(C4*Y4) -> 0 | L4: =SUM(C4*Z4) -> 0 | M4: =SUM(D4*Y4) -> 0 | N4: =SUM(D4*Z4) -> 0 | O4: =SUM(E4*Y4) -> 0 | P4: =SUM(E4*Z4) -> 0 | Q4: =SUM(F4*Y4) -> 0 | R4: =SUM(F4*Z4) -> 0 | S4: =SUM(G4*Y4) -> 0 | T4: =SUM(G4*Z4) -> 0 | U4: =SUM(H4*Y4) -> 0 | V4: =SUM(H4*Z4) -> 0 | W4: =SUM(I4*Y4) -> 0 | X4: =SUM(I4*Z4) -> 0 | Y4: =SUM(PRECIOS!C4) -> 89 | Z4: =SUM(PRECIOS!D4) -> 89 | AA4: =Y4*J4 -> 0 | AB4: =Z4*J4 -> 0 | AC4: =AB4-AA4 -> 0
A5: 2 | B5: =(PRECIOS!B5) -> LOMO DE CERDO | C5: =SUM('ORDENES '!O4) -> 0 | D5: =SUM('ORDENES '!P4) -> 0 | E5: =SUM('ORDENES '!Q4) -> 0 | F5: =SUM('ORDENES '!R4) -> 10 | G5: =SUM('ORDENES '!S4) -> 17 | H5: =SUM('ORDENES '!T4) -> 0 | I5: =SUM('ORDENES '!U4) -> 17 | J5: =SUM(C5:I5) -> 44 | K5: =SUM(C5*Y5) -> 0 | L5: =SUM(C5*Z5) -> 0 | M5: =SUM(D5*Y5) -> 0 | N5: =SUM(D5*Z5) -> 0 | O5: =SUM(E5*Y5) -> 0 | P5: =SUM(E5*Z5) -> 0 | Q5: =SUM(F5*Y5) -> 500 | R5: =SUM(F5*Z5) -> 950 | S5: =SUM(G5*Y5) -> 850 | T5: =SUM(G5*Z5) -> 1615 | U5: =SUM(H5*Y5) -> 0 | V5: =SUM(H5*Z5) -> 0 | W5: =SUM(I5*Y5) -> 850 | X5: =SUM(I5*Z5) -> 1615 | Y5: =SUM(PRECIOS!C5) -> 50 | Z5: =SUM(PRECIOS!D5) -> 95 | AA5: =Y5*J5 -> 2200 | AB5: =Z5*J5 -> 4180 | AC5: =AB5-AA5 -> 1980
A6: 3 | B6: =(PRECIOS!B6) -> PIERNA DE CERDO EN TROZO | C6: =SUM('ORDENES '!O5) -> 0 | D6: =SUM('ORDENES '!P5) -> 0 | E6: =SUM('ORDENES '!Q5) -> 17 | F6: =SUM('ORDENES '!R5) -> 0 | G6: =SUM('ORDENES '!S5) -> 0 | H6: =SUM('ORDENES '!T5) -> 0 | I6: =SUM('ORDENES '!U5) -> 0 | J6: =SUM(C6:I6) -> 17 | K6: =SUM(C6*Y6) -> 0 | L6: =SUM(C6*Z6) -> 0 | M6: =SUM(D6*Y6) -> 0 | N6: =SUM(D6*Z6) -> 0 | O6: =SUM(E6*Y6) -> 1088 | P6: =SUM(E6*Z6) -> 1394 | Q6: =SUM(F6*Y6) -> 0 | R6: =SUM(F6*Z6) -> 0 | S6: =SUM(G6*Y6) -> 0 | T6: =SUM(G6*Z6) -> 0 | U6: =SUM(H6*Y6) -> 0 | V6: =SUM(H6*Z6) -> 0 | W6: =SUM(I6*Y6) -> 0 | X6: =SUM(I6*Z6) -> 0 | Y6: =SUM(PRECIOS!C6) -> 64 | Z6: =SUM(PRECIOS!D6) -> 82 | AA6: =Y6*J6 -> 1088 | AB6: =Z6*J6 -> 1394 | AC6: =AB6-AA6 -> 306
A7: 4 | B7: =(PRECIOS!B7) -> PIERNA DE CERDO MOLIDA | C7: =SUM('ORDENES '!O6) -> 0 | D7: =SUM('ORDENES '!P6) -> 0 | E7: =SUM('ORDENES '!Q6) -> 0 | F7: =SUM('ORDENES '!R6) -> 0 | G7: =SUM('ORDENES '!S6) -> 0 | H7: =SUM('ORDENES '!T6) -> 0 | I7: =SUM('ORDENES '!U6) -> 0 | J7: =SUM(C7:I7) -> 0 | K7: =SUM(C7*Y7) -> 0 | L7: =SUM(C7*Z7) -> 0 | M7: =SUM(D7*Y7) -> 0 | N7: =SUM(D7*Z7) -> 0 | O7: =SUM(E7*Y7) -> 0 | P7: =SUM(E7*Z7) -> 0 | Q7: =SUM(F7*Y7) -> 0 | R7: =SUM(F7*Z7) -> 0 | S7: =SUM(G7*Y7) -> 0 | T7: =SUM(G7*Z7) -> 0 | U7: =SUM(H7*Y7) -> 0 | V7: =SUM(H7*Z7) -> 0 | W7: =SUM(I7*Y7) -> 0 | X7: =SUM(I7*Z7) -> 0 | Y7: =SUM(PRECIOS!C7) -> 50 | Z7: =SUM(PRECIOS!D7) -> 60 | AA7: =Y7*J7 -> 0 | AB7: =Z7*J7 -> 0 | AC7: =AB7-AA7 -> 0
A8: 5 | B8: =(PRECIOS!B8) -> MERO EN FILETE CONGELADO | C8: =SUM('ORDENES '!O7) -> 0 | D8: =SUM('ORDENES '!P7) -> 0 | E8: =SUM('ORDENES '!Q7) -> 0 | F8: =SUM('ORDENES '!R7) -> 0 | G8: =SUM('ORDENES '!S7) -> 0 | H8: =SUM('ORDENES '!T7) -> 33 | I8: =SUM('ORDENES '!U7) -> 0 | J8: =SUM(C8:I8) -> 33 | K8: =SUM(C8*Y8) -> 0 | L8: =SUM(C8*Z8) -> 0 | M8: =SUM(D8*Y8) -> 0 | N8: =SUM(D8*Z8) -> 0 | O8: =SUM(E8*Y8) -> 0 | P8: =SUM(E8*Z8) -> 0 | Q8: =SUM(F8*Y8) -> 0 | R8: =SUM(F8*Z8) -> 0 | S8: =SUM(G8*Y8) -> 0 | T8: =SUM(G8*Z8) -> 0 | U8: =SUM(H8*Y8) -> 1877.7 | V8: =SUM(H8*Z8) -> 2970 | W8: =SUM(I8*Y8) -> 0 | X8: =SUM(I8*Z8) -> 0 | Y8: =SUM(PRECIOS!C8) -> 56.9 | Z8: =SUM(PRECIOS!D8) -> 90 | AA8: =Y8*J8 -> 1877.7 | AB8: =Z8*J8 -> 2970 | AC8: =AB8-AA8 -> 1092.3
A9: 6 | B9: =(PRECIOS!B9) -> PECHUGA DE POLLO | C9: =SUM('ORDENES '!O8) -> 0 | D9: =SUM('ORDENES '!P8) -> 0 | E9: =SUM('ORDENES '!Q8) -> 0 | F9: =SUM('ORDENES '!R8) -> 0 | G9: =SUM('ORDENES '!S8) -> 0 | H9: =SUM('ORDENES '!T8) -> 0 | I9: =SUM('ORDENES '!U8) -> 0 | J9: =SUM(C9:I9) -> 0 | K9: =SUM(C9*Y9) -> 0 | L9: =SUM(C9*Z9) -> 0 | M9: =SUM(D9*Y9) -> 0 | N9: =SUM(D9*Z9) -> 0 | O9: =SUM(E9*Y9) -> 0 | P9: =SUM(E9*Z9) -> 0 | Q9: =SUM(F9*Y9) -> 0 | R9: =SUM(F9*Z9) -> 0 | S9: =SUM(G9*Y9) -> 0 | T9: =SUM(G9*Z9) -> 0 | U9: =SUM(H9*Y9) -> 0 | V9: =SUM(H9*Z9) -> 0 | W9: =SUM(I9*Y9) -> 0 | X9: =SUM(I9*Z9) -> 0 | Y9: =SUM(PRECIOS!C9) -> 0 | Z9: =SUM(PRECIOS!D9) -> 98 | AA9: =Y9*J9 -> 0 | AB9: =Z9*J9 -> 0 | AC9: =AB9-AA9 -> 0
A10: 6 | B10: =(PRECIOS!B10) -> PECHUGA DE POLLO DESHUESADA | C10: =SUM('ORDENES '!O9) -> 7 | D10: =SUM('ORDENES '!P9) -> 16 | E10: =SUM('ORDENES '!Q9) -> 1.5 | F10: =SUM('ORDENES '!R9) -> 13 | G10: =SUM('ORDENES '!S9) -> 22 | H10: =SUM('ORDENES '!T9) -> 2.5 | I10: =SUM('ORDENES '!U9) -> 28 | J10: =SUM(C10:I10) -> 90 | K10: =SUM(C10*Y10) -> 516.6 | L10: =SUM(C10*Z10) -> 1050 | M10: =SUM(D10*Y10) -> 1180.8 | N10: =SUM(D10*Z10) -> 2400 | O10: =SUM(E10*Y10) -> 110.7 | P10: =SUM(E10*Z10) -> 225 | Q10: =SUM(F10*Y10) -> 959.4 | R10: =SUM(F10*Z10) -> 1950 | S10: =SUM(G10*Y10) -> 1623.6 | T10: =SUM(G10*Z10) -> 3300 | U10: =SUM(H10*Y10) -> 184.5 | V10: =SUM(H10*Z10) -> 375 | W10: =SUM(I10*Y10) -> 2066.4 | X10: =SUM(I10*Z10) -> 4200 | Y10: =SUM(PRECIOS!C10) -> 73.8 | Z10: =SUM(PRECIOS!D10) -> 150 | AA10: =Y10*J10 -> 6642 | AB10: =Z10*J10 -> 13500 | AC10: =AB10-AA10 -> 6858
A11: 7 | B11: =(PRECIOS!B11) -> PECHUGA DESHUESADA EN BISTEC | C11: =SUM('ORDENES '!O10) -> 1 | D11: =SUM('ORDENES '!P10) -> 3.5 | E11: =SUM('ORDENES '!Q10) -> 9 | F11: =SUM('ORDENES '!R10) -> 1 | G11: =SUM('ORDENES '!S10) -> 0 | H11: =SUM('ORDENES '!T10) -> 0 | I11: =SUM('ORDENES '!U10) -> 0 | J11: =SUM(C11:I11) -> 14.5 | K11: =SUM(C11*Y11) -> 73.8 | L11: =SUM(C11*Z11) -> 150 | M11: =SUM(D11*Y11) -> 258.3 | N11: =SUM(D11*Z11) -> 525 | O11: =SUM(E11*Y11) -> 664.2 | P11: =SUM(E11*Z11) -> 1350 | Q11: =SUM(F11*Y11) -> 73.8 | R11: =SUM(F11*Z11) -> 150 | S11: =SUM(G11*Y11) -> 0 | T11: =SUM(G11*Z11) -> 0 | U11: =SUM(H11*Y11) -> 0 | V11: =SUM(H11*Z11) -> 0 | W11: =SUM(I11*Y11) -> 0 | X11: =SUM(I11*Z11) -> 0 | Y11: =SUM(PRECIOS!C11) -> 73.8 | Z11: =SUM(PRECIOS!D11) -> 150 | AA11: =Y11*J11 -> 1070.1 | AB11: =Z11*J11 -> 2175 | AC11: =AB11-AA11 -> 1104.9
A12: 8 | B12: =(PRECIOS!B12) -> PECHUGA DE POLLO MÓLIDA | C12: =SUM('ORDENES '!O11) -> 0 | D12: =SUM('ORDENES '!P11) -> 0 | E12: =SUM('ORDENES '!Q11) -> 0 | F12: =SUM('ORDENES '!R11) -> 0 | G12: =SUM('ORDENES '!S11) -> 0 | H12: =SUM('ORDENES '!T11) -> 0 | I12: =SUM('ORDENES '!U11) -> 0 | J12: =SUM(C12:I12) -> 0 | K12: =SUM(C12*Y12) -> 0 | L12: =SUM(C12*Z12) -> 0 | M12: =SUM(D12*Y12) -> 0 | N12: =SUM(D12*Z12) -> 0 | O12: =SUM(E12*Y12) -> 0 | P12: =SUM(E12*Z12) -> 0 | Q12: =SUM(F12*Y12) -> 0 | R12: =SUM(F12*Z12) -> 0 | S12: =SUM(G12*Y12) -> 0 | T12: =SUM(G12*Z12) -> 0 | U12: =SUM(H12*Y12) -> 0 | V12: =SUM(H12*Z12) -> 0 | W12: =SUM(I12*Y12) -> 0 | X12: =SUM(I12*Z12) -> 0 | Y12: =SUM(PRECIOS!C12) -> 55 | Z12: =SUM(PRECIOS!D12) -> 75 | AA12: =Y12*J12 -> 0 | AB12: =Z12*J12 -> 0 | AC12: =AB12-AA12 -> 0
A13: 9 | B13: =(PRECIOS!B13) -> PIERNA Y MUSLO DE POLLO SIN PIEL EN FORMA DE PISTOLA | C13: =SUM('ORDENES '!O12) -> 15 | D13: =SUM('ORDENES '!P12) -> 25 | E13: =SUM('ORDENES '!Q12) -> 0 | F13: =SUM('ORDENES '!R12) -> 21 | G13: =SUM('ORDENES '!S12) -> 0 | H13: =SUM('ORDENES '!T12) -> 13 | I13: =SUM('ORDENES '!U12) -> 0 | J13: =SUM(C13:I13) -> 74 | K13: =SUM(C13*Y13) -> 537 | L13: =SUM(C13*Z13) -> 975 | M13: =SUM(D13*Y13) -> 895 | N13: =SUM(D13*Z13) -> 1625 | O13: =SUM(E13*Y13) -> 0 | P13: =SUM(E13*Z13) -> 0 | Q13: =SUM(F13*Y13) -> 751.8 | R13: =SUM(F13*Z13) -> 1365 | S13: =SUM(G13*Y13) -> 0 | T13: =SUM(G13*Z13) -> 0 | U13: =SUM(H13*Y13) -> 465.4 | V13: =SUM(H13*Z13) -> 845 | W13: =SUM(I13*Y13) -> 0 | X13: =SUM(I13*Z13) -> 0 | Y13: =SUM(PRECIOS!C13) -> 35.8 | Z13: =SUM(PRECIOS!D13) -> 65 | AA13: =Y13*J13 -> 2649.2 | AB13: =Z13*J13 -> 4810 | AC13: =AB13-AA13 -> 2160.8
A14: 10 | B14: =(PRECIOS!B14) -> POLLO ENTERO | C14: =SUM('ORDENES '!O13) -> 0 | D14: =SUM('ORDENES '!P13) -> 0 | E14: =SUM('ORDENES '!Q13) -> 0 | F14: =SUM('ORDENES '!R13) -> 0 | G14: =SUM('ORDENES '!S13) -> 0 | H14: =SUM('ORDENES '!T13) -> 0 | I14: =SUM('ORDENES '!U13) -> 0 | J14: =SUM(C14:I14) -> 0 | K14: =SUM(C14*Y14) -> 0 | L14: =SUM(C14*Z14) -> 0 | M14: =SUM(D14*Y14) -> 0 | N14: =SUM(D14*Z14) -> 0 | O14: =SUM(E14*Y14) -> 0 | P14: =SUM(E14*Z14) -> 0 | Q14: =SUM(F14*Y14) -> 0 | R14: =SUM(F14*Z14) -> 0 | S14: =SUM(G14*Y14) -> 0 | T14: =SUM(G14*Z14) -> 0 | U14: =SUM(H14*Y14) -> 0 | V14: =SUM(H14*Z14) -> 0 | W14: =SUM(I14*Y14) -> 0 | X14: =SUM(I14*Z14) -> 0 | Y14: =SUM(PRECIOS!C14) -> 50 | Z14: =SUM(PRECIOS!D14) -> 50 | AA14: =Y14*J14 -> 0 | AB14: =Z14*J14 -> 0 | AC14: =AB14-AA14 -> 0
A15: 11 | B15: =(PRECIOS!B15) -> BISTEC DE PIERNA DE RES | C15: =SUM('ORDENES '!O14) -> 0 | D15: =SUM('ORDENES '!P14) -> 13 | E15: =SUM('ORDENES '!Q14) -> 8 | F15: =SUM('ORDENES '!R14) -> 21 | G15: =SUM('ORDENES '!S14) -> 11 | H15: =SUM('ORDENES '!T14) -> 0 | I15: =SUM('ORDENES '!U14) -> 0 | J15: =SUM(C15:I15) -> 53 | K15: =SUM(C15*Y15) -> 0 | L15: =SUM(C15*Z15) -> 0 | M15: =SUM(D15*Y15) -> 1820 | N15: =SUM(D15*Z15) -> 2080 | O15: =SUM(E15*Y15) -> 1120 | P15: =SUM(E15*Z15) -> 1280 | Q15: =SUM(F15*Y15) -> 2940 | R15: =SUM(F15*Z15) -> 3360 | S15: =SUM(G15*Y15) -> 1540 | T15: =SUM(G15*Z15) -> 1760 | U15: =SUM(H15*Y15) -> 0 | V15: =SUM(H15*Z15) -> 0 | W15: =SUM(I15*Y15) -> 0 | X15: =SUM(I15*Z15) -> 0 | Y15: =SUM(PRECIOS!C15) -> 140 | Z15: =SUM(PRECIOS!D15) -> 160 | AA15: =Y15*J15 -> 7420 | AB15: =Z15*J15 -> 8480 | AC15: =AB15-AA15 -> 1060
... A28: 24 | B28: =(PRECIOS!B28) -> TOCINO | C28: =SUM('ORDENES '!O27) -> 0.7 | D28: =SUM('ORDENES '!P27) -> 0 | E28: =SUM('ORDENES '!Q27) -> 0.8 | F28: =SUM('ORDENES '!R27) -> 0 | G28: =SUM('ORDENES '!S27) -> 0 | H28: =SUM('ORDENES '!T27) -> 0.7 | I28: =SUM('ORDENES '!U27) -> 0 | J28: =SUM(C28:I28) -> 2.2 | K28: =SUM(C28*Y28) -> 63 | L28: =SUM(C28*Z28) -> 98 | M28: =SUM(D28*Y28) -> 0 | N28: =SUM(D28*Z28) -> 0 | O28: =SUM(E28*Y28) -> 72 | P28: =SUM(E28*Z28) -> 112 | Q28: =SUM(F28*Y28) -> 0 | R28: =SUM(F28*Z28) -> 0 | S28: =SUM(G28*Y28) -> 0 | T28: =SUM(G28*Z28) -> 0 | U28: =SUM(H28*Y28) -> 63 | V28: =SUM(H28*Z28) -> 98 | W28: =SUM(I28*Y28) -> 0 | X28: =SUM(I28*Z28) -> 0 | Y28: =SUM(PRECIOS!C28) -> 90 | Z28: =SUM(PRECIOS!D28) -> 140 | AA28: =Y28*J28 -> 198 | AB28: =Z28*J28 -> 308 | AC28: =AB28-AA28 -> 110
J29: =SUM(J4:J28) -> 517.7 | K29: =SUM(K4:K28) -> 4480.3 | L29: =SUM(L4:L28) -> 7744 | M29: =SUM(M4:M28) -> 4649.1 | N29: =SUM(N4:N28) -> 7600 | O29: =SUM(O4:O28) -> 4527.4 | P29: =SUM(P4:P28) -> 6606 | Q29: =SUM(Q4:Q28) -> 5757.65 | ... X29: =SUM(X4:X28) -> 8347 | AA29: =SUM(K29,M29,O29,Q29,S29,U29,W29) -> 33006.25 | AB29: =SUM(L29,N29,P29,R29,T29,V29,X29) -> 54302 | AC29: =SUM(AB29-AA29) -> 21295.75

Sheet IMSS3
C1: =('ORDENES '!L1) -> 11-17 enero
K2: CLINICA IMMS 3
A3: No. | B3: Producto | C3: Martes | D3: Miercoles | E3: Jueves | F3: Viernes | G3: Sabado | H3: domingo | I3: Lunes | J3: Total / semana | K3: Importe Martes | L3: Nota Martes | M3: Imp Miercoles | N3: Nota Miercoles | O3: Imp. Jueves | P3: Nota Jueves | Q3: Imp. Viernes | R3: Nota Viernes | S3: Imp. Sabado | T3: Nota Sabado | U3: Imp. Domingo | V3: Nota Domingo | W3: Imp. Lunes | X3: Nota Lunes | Y3: PRECIO COSTO | Z3: PRECIO VENTA | AA3: Total Compra | AB3: Total Venta | AC3: Utilidad
A4: 1 | B4: =(PRECIOS!B4) -> CHULETA DE CERDO | C4: =SUM('ORDENES '!D31) -> 0 | D4: =SUM('ORDENES '!E31) -> 0 | E4: =SUM('ORDENES '!F31) -> 0 | F4: =SUM('ORDENES '!G31) -> 0 | G4: =SUM('ORDENES '!H31) -> 0 | H4: =SUM('ORDENES '!I31) -> 0 | I4: =SUM('ORDENES '!J31) -> 0 | J4: =SUM(C4:I4) -> 0 | K4: =SUM(C4*Y4) -> 0 | L4: =SUM(C4*Z4) -> 0 | M4: =SUM(D4*Y4) -> 0 | N4: =SUM(D4*Z4) -> 0 | O4: =SUM(E4*Y4) -> 0 | P4: =SUM(E4*Z4) -> 0 | Q4: =SUM(F4*Y4) -> 0 | R4: =SUM(F4*Z4) -> 0 | S4: =SUM(G4*Y4) -> 0 | T4: =SUM(G4*Z4) -> 0 | U4: =SUM(H4*Y4) -> 0 | V4: =SUM(H4*Z4) -> 0 | W4: =SUM(I4*Y4) -> 0 | X4: =SUM(I4*Z4) -> 0 | Y4: =SUM(PRECIOS!C4) -> 89 | Z4: =SUM(PRECIOS!D4) -> 89 | AA4: =Y4*J4 -> 0 | AB4: =Z4*J4 -> 0 | AC4: =AB4-AA4 -> 0
A5: 2 | B5: =(PRECIOS!B5) -> LOMO DE CERDO | C5: =SUM('ORDENES '!D32) -> 0 | D5: =SUM('ORDENES '!E32) -> 0 | E5: =SUM('ORDENES '!F32) -> 0 | F5: =SUM('ORDENES '!G32) -> 7.2 | G5: =SUM('ORDENES '!H32) -> 7.8 | H5: =SUM('ORDENES '!I32) -> 0 | I5: =SUM('ORDENES '!J32) -> 9 | J5: =SUM(C5:I5) -> 24 | K5: =SUM(C5*Y5) -> 0 | L5: =SUM(C5*Z5) -> 0 | M5: =SUM(D5*Y5) -> 0 | N5: =SUM(D5*Z5) -> 0 | O5: =SUM(E5*Y5) -> 0 | P5: =SUM(E5*Z5) -> 0 | Q5: =SUM(F5*Y5) -> 360 | R5: =SUM(F5*Z5) -> 684 | S5: =SUM(G5*Y5) -> 390 | T5: =SUM(G5*Z5) -> 741 | U5: =SUM(H5*Y5) -> 0 | V5: =SUM(H5*Z5) -> 0 | W5: =SUM(I5*Y5) -> 450 | X5: =SUM(I5*Z5) -> 855 | Y5: =SUM(PRECIOS!C5) -> 50 | Z5: =SUM(PRECIOS!D5) -> 95 | AA5: =Y5*J5 -> 1200 | AB5: =Z5*J5 -> 2280 | AC5: =AB5-AA5 -> 1080
A6: 3 | B6: =(PRECIOS!B6) -> PIERNA DE CERDO EN TROZO | C6: =SUM('ORDENES '!D33) -> 0 | D6: =SUM('ORDENES '!E33) -> 0 | E6: =SUM('ORDENES '!F33) -> 9 | F6: =SUM('ORDENES '!G33) -> 0 | G6: =SUM('ORDENES '!H33) -> 0 | H6: =SUM('ORDENES '!I33) -> 0 | I6: =SUM('ORDENES '!J33) -> 0 | J6: =SUM(C6:I6) -> 9 | K6: =SUM(C6*Y6) -> 0 | L6: =SUM(C6*Z6) -> 0 | M6: =SUM(D6*Y6) -> 0 | N6: =SUM(D6*Z6) -> 0 | O6: =SUM(E6*Y6) -> 576 | P6: =SUM(E6*Z6) -> 738 | Q6: =SUM(F6*Y6) -> 0 | R6: =SUM(F6*Z6) -> 0 | S6: =SUM(G6*Y6) -> 0 | T6: =SUM(G6*Z6) -> 0 | U6: =SUM(H6*Y6) -> 0 | V6: =SUM(H6*Z6) -> 0 | W6: =SUM(I6*Y6) -> 0 | X6: =SUM(I6*Z6) -> 0 | Y6: =SUM(PRECIOS!C6) -> 64 | Z6: =SUM(PRECIOS!D6) -> 82 | AA6: =Y6*J6 -> 576 | AB6: =Z6*J6 -> 738 | AC6: =AB6-AA6 -> 162
A7: 4 | B7: =(PRECIOS!B7) -> PIERNA DE CERDO MOLIDA | C7: =SUM('ORDENES '!D34) -> 0 | D7: =SUM('ORDENES '!E34) -> 0 | E7: =SUM('ORDENES '!F34) -> 0 | F7: =SUM('ORDENES '!G34) -> 0 | G7: =SUM('ORDENES '!H34) -> 0 | H7: =SUM('ORDENES '!I34) -> 0 | I7: =SUM('ORDENES '!J34) -> 0 | J7: =SUM(C7:I7) -> 0 | K7: =SUM(C7*Y7) -> 0 | L7: =SUM(C7*Z7) -> 0 | M7: =SUM(D7*Y7) -> 0 | N7: =SUM(D7*Z7) -> 0 | O7: =SUM(E7*Y7) -> 0 | P7: =SUM(E7*Z7) -> 0 | Q7: =SUM(F7*Y7) -> 0 | R7: =SUM(F7*Z7) -> 0 | S7: =SUM(G7*Y7) -> 0 | T7: =SUM(G7*Z7) -> 0 | U7: =SUM(H7*Y7) -> 0 | V7: =SUM(H7*Z7) -> 0 | W7: =SUM(I7*Y7) -> 0 | X7: =SUM(I7*Z7) -> 0 | Y7: =SUM(PRECIOS!C7) -> 50 | Z7: =SUM(PRECIOS!D7) -> 60 | AA7: =Y7*J7 -> 0 | AB7: =Z7*J7 -> 0 | AC7: =AB7-AA7 -> 0
A8: 5 | B8: =(PRECIOS!B8) -> MERO EN FILETE CONGELADO | C8: =SUM('ORDENES '!D35) -> 0 | D8: =SUM('ORDENES '!E35) -> 0 | E8: =SUM('ORDENES '!F35) -> 0 | F8: =SUM('ORDENES '!G35) -> 0 | G8: =SUM('ORDENES '!H35) -> 0 | H8: =SUM('ORDENES '!I35) -> 19.5 | I8: =SUM('ORDENES '!J35) -> 0 | J8: =SUM(C8:I8) -> 19.5 | K8: =SUM(C8*Y8) -> 0 | L8: =SUM(C8*Z8) -> 0 | M8: =SUM(D8*Y8) -> 0 | N8: =SUM(D8*Z8) -> 0 | O8: =SUM(E8*Y8) -> 0 | P8: =SUM(E8*Z8) -> 0 | Q8: =SUM(F8*Y8) -> 0 | R8: =SUM(F8*Z8) -> 0 | S8: =SUM(G8*Y8) -> 0 | T8: =SUM(G8*Z8) -> 0 | U8: =SUM(H8*Y8) -> 1109.55 | V8: =SUM(H8*Z8) -> 1755 | W8: =SUM(I8*Y8) -> 0 | X8: =SUM(I8*Z8) -> 0 | Y8: =SUM(PRECIOS!C8) -> 56.9 | Z8: =SUM(PRECIOS!D8) -> 90 | AA8: =Y8*J8 -> 1109.55 | AB8: =Z8*J8 -> 1755 | AC8: =AB8-AA8 -> 645.45
A9: 6 | B9: =(PRECIOS!B9) -> PECHUGA DE POLLO | C9: =SUM('ORDENES '!D36) -> 0 | D9: =SUM('ORDENES '!E36) -> 0 | E9: =SUM('ORDENES '!F36) -> 0 | F9: =SUM('ORDENES '!G36) -> 0 | G9: =SUM('ORDENES '!H36) -> 0 | H9: =SUM('ORDENES '!I36) -> 0 | I9: =SUM('ORDENES '!J36) -> 0 | J9: =SUM(C9:I9) -> 0 | K9: =SUM(C9*Y9) -> 0 | L9: =SUM(C9*Z9) -> 0 | M9: =SUM(D9*Y9) -> 0 | N9: =SUM(D9*Z9) -> 0 | O9: =SUM(E9*Y9) -> 0 | P9: =SUM(E9*Z9) -> 0 | Q9: =SUM(F9*Y9) -> 0 | R9: =SUM(F9*Z9) -> 0 | S9: =SUM(G9*Y9) -> 0 | T9: =SUM(G9*Z9) -> 0 | U9: =SUM(H9*Y9) -> 0 | V9: =SUM(H9*Z9) -> 0 | W9: =SUM(I9*Y9) -> 0 | X9: =SUM(I9*Z9) -> 0 | Y9: =SUM(PRECIOS!C9) -> 0 | Z9: =SUM(PRECIOS!D9) -> 98 | AA9: =Y9*J9 -> 0 | AB9: =Z9*J9 -> 0 | AC9: =AB9-AA9 -> 0
A10: 6 | B10: =(PRECIOS!B10) -> PECHUGA DE POLLO DESHUESADA | C10: =SUM('ORDENES '!D37) -> 8.15 | D10: =SUM('ORDENES '!E37) -> 17.5 | E10: =SUM('ORDENES '!F37) -> 1.1 | F10: =SUM('ORDENES '!G37) -> 12.3 | G10: =SUM('ORDENES '!H37) -> 19.1 | H10: =SUM('ORDENES '!I37) -> 3.13 | I10: =SUM('ORDENES '!J37) -> 21.38 | J10: =SUM(C10:I10) -> 82.66 | K10: =SUM(C10*Y10) -> 601.47 | L10: =SUM(C10*Z10) -> 1222.5 | M10: =SUM(D10*Y10) -> 1291.5 | N10: =SUM(D10*Z10) -> 2625 | O10: =SUM(E10*Y10) -> 81.18 | P10: =SUM(E10*Z10) -> 165 | Q10: =SUM(F10*Y10) -> 907.74 | R10: =SUM(F10*Z10) -> 1845 | S10: =SUM(G10*Y10) -> 1409.58 | T10: =SUM(G10*Z10) -> 2865 | U10: =SUM(H10*Y10) -> 230.994 | V10: =SUM(H10*Z10) -> 469.5 | W10: =SUM(I10*Y10) -> 1577.844 | X10: =SUM(I10*Z10) -> 3207 | Y10: =SUM(PRECIOS!C10) -> 73.8 | Z10: =SUM(PRECIOS!D10) -> 150 | AA10: =Y10*J10 -> 6100.308 | AB10: =Z10*J10 -> 12399 | AC10: =AB10-AA10 -> 6298.692
A11: 7 | B11: =(PRECIOS!B11) -> PECHUGA DESHUESADA EN BISTEC | C11: =SUM('ORDENES '!D38) -> 1.35 | D11: =SUM('ORDENES '!E38) -> 2.7 | E11: =SUM('ORDENES '!F38) -> 9.27 | F11: =SUM('ORDENES '!G38) -> 1.35 | G11: =SUM('ORDENES '!H38) -> 0 | H11: =SUM('ORDENES '!I38) -> 0 | I11: =SUM('ORDENES '!J38) -> 0 | J11: =SUM(C11:I11) -> 14.67 | K11: =SUM(C11*Y11) -> 99.63 | L11: =SUM(C11*Z11) -> 202.5 | M11: =SUM(D11*Y11) -> 199.26 | N11: =SUM(D11*Z11) -> 405 | O11: =SUM(E11*Y11) -> 684.126 | P11: =SUM(E11*Z11) -> 1390.5 | Q11: =SUM(F11*Y11) -> 99.63 | R11: =SUM(F11*Z11) -> 202.5 | S11: =SUM(G11*Y11) -> 0 | T11: =SUM(G11*Z11) -> 0 | U11: =SUM(H11*Y11) -> 0 | V11: =SUM(H11*Z11) -> 0 | W11: =SUM(I11*Y11) -> 0 | X11: =SUM(I11*Z11) -> 0 | Y11: =SUM(PRECIOS!C11) -> 73.8 | Z11: =SUM(PRECIOS!D11) -> 150 | AA11: =Y11*J11 -> 1082.646 | AB11: =Z11*J11 -> 2200.5 | AC11: =AB11-AA11 -> 1117.854
A12: 8 | B12: =(PRECIOS!B12) -> PECHUGA DE POLLO MÓLIDA | C12: =SUM('ORDENES '!D39) -> 0 | D12: =SUM('ORDENES '!E39) -> 0 | E12: =SUM('ORDENES '!F39) -> 0 | F12: =SUM('ORDENES '!G39) -> 0 | G12: =SUM('ORDENES '!H39) -> 0 | H12: =SUM('ORDENES '!I39) -> 0 | I12: =SUM('ORDENES '!J39) -> 0 | J12: =SUM(C12:I12) -> 0 | K12: =SUM(C12*Y12) -> 0 | L12: =SUM(C12*Z12) -> 0 | M12: =SUM(D12*Y12) -> 0 | N12: =SUM(D12*Z12) -> 0 | O12: =SUM(E12*Y12) -> 0 | P12: =SUM(E12*Z12) -> 0 | Q12: =SUM(F12*Y12) -> 0 | R12: =SUM(F12*Z12) -> 0 | S12: =SUM(G12*Y12) -> 0 | T12: =SUM(G12*Z12) -> 0 | U12: =SUM(H12*Y12) -> 0 | V12: =SUM(H12*Z12) -> 0 | W12: =SUM(I12*Y12) -> 0 | X12: =SUM(I12*Z12) -> 0 | Y12: =SUM(PRECIOS!C12) -> 55 | Z12: =SUM(PRECIOS!D12) -> 75 | AA12: =Y12*J12 -> 0 | AB12: =Z12*J12 -> 0 | AC12: =AB12-AA12 -> 0
A13: 9 | B13: =(PRECIOS!B13) -> PIERNA Y MUSLO DE POLLO SIN PIEL EN FORMA DE PISTOLA | C13: =SUM('ORDENES '!D40) -> 12.45 | D13: =SUM('ORDENES '!E40) -> 15.75 | E13: =SUM('ORDENES '!F40) -> 0 | F13: =SUM('ORDENES '!G40) -> 9.75 | G13: =SUM('ORDENES '!H40) -> 0 | H13: =SUM('ORDENES '!I40) -> 15.45 | I13: =SUM('ORDENES '!J40) -> 0 | J13: =SUM(C13:I13) -> 53.4 | K13: =SUM(C13*Y13) -> 445.71 | L13: =SUM(C13*Z13) -> 809.25 | M13: =SUM(D13*Y13) -> 563.85 | N13: =SUM(D13*Z13) -> 1023.75 | O13: =SUM(E13*Y13) -> 0 | P13: =SUM(E13*Z13) -> 0 | Q13: =SUM(F13*Y13) -> 349.05 | R13: =SUM(F13*Z13) -> 633.75 | S13: =SUM(G13*Y13) -> 0 | T13: =SUM(G13*Z13) -> 0 | U13: =SUM(H13*Y13) -> 553.11 | V13: =SUM(H13*Z13) -> 1004.25 | W13: =SUM(I13*Y13) -> 0 | X13: =SUM(I13*Z13) -> 0 | Y13: =SUM(PRECIOS!C13) -> 35.8 | Z13: =SUM(PRECIOS!D13) -> 65 | AA13: =Y13*J13 -> 1911.72 | AB13: =Z13*J13 -> 3471 | AC13: =AB13-AA13 -> 1559.28
A14: 10 | B14: =(PRECIOS!B14) -> POLLO ENTERO | C14: =SUM('ORDENES '!D41) -> 0 | D14: =SUM('ORDENES '!E41) -> 0 | E14: =SUM('ORDENES '!F41) -> 0 | F14: =SUM('ORDENES '!G41) -> 0 | G14: =SUM('ORDENES '!H41) -> 0 | H14: =SUM('ORDENES '!I41) -> 0 | I14: =SUM('ORDENES '!J41) -> 0 | J14: =SUM(C14:I14) -> 0 | K14: =SUM(C14*Y14) -> 0 | L14: =SUM(C14*Z14) -> 0 | M14: =SUM(D14*Y14) -> 0 | N14: =SUM(D14*Z14) -> 0 | O14: =SUM(E14*Y14) -> 0 | P14: =SUM(E14*Z14) -> 0 | Q14: =SUM(F14*Y14) -> 0 | R14: =SUM(F14*Z14) -> 0 | S14: =SUM(G14*Y14) -> 0 | T14: =SUM(G14*Z14) -> 0 | U14: =SUM(H14*Y14) -> 0 | V14: =SUM(H14*Z14) -> 0 | W14: =SUM(I14*Y14) -> 0 | X14: =SUM(I14*Z14) -> 0 | Y14: =SUM(PRECIOS!C14) -> 50 | Z14: =SUM(PRECIOS!D14) -> 50 | AA14: =Y14*J14 -> 0 | AB14: =Z14*J14 -> 0 | AC14: =AB14-AA14 -> 0
A15: 11 | B15: =(PRECIOS!B15) -> BISTEC DE PIERNA DE RES | C15: =SUM('ORDENES '!D42) -> 0 | D15: =SUM('ORDENES '!E42) -> 9.6 | E15: =SUM('ORDENES '!F42) -> 6 | F15: =SUM('ORDENES '!G42) -> 14.7 | G15: =SUM('ORDENES '!H42) -> 9 | H15: =SUM('ORDENES '!I42) -> 0 | I15: =SUM('ORDENES '!J42) -> 0 | J15: =SUM(C15:I15) -> 39.3 | K15: =SUM(C15*Y15) -> 0 | L15: =SUM(C15*Z15) -> 0 | M15: =SUM(D15*Y15) -> 1344 | N15: =SUM(D15*Z15) -> 1536 | O15: =SUM(E15*Y15) -> 840 | P15: =SUM(E15*Z15) -> 960 | Q15: =SUM(F15*Y15) -> 2058 | R15: =SUM(F15*Z15) -> 2352 | S15: =SUM(G15*Y15) -> 1260 | T15: =SUM(G15*Z15) -> 1440 | U15: =SUM(H15*Y15) -> 0 | V15: =SUM(H15*Z15) -> 0 | W15: =SUM(I15*Y15) -> 0 | X15: =SUM(I15*Z15) -> 0 | Y15: =SUM(PRECIOS!C15) -> 140 | Z15: =SUM(PRECIOS!D15) -> 160 | AA15: =Y15*J15 -> 5502 | AB15: =Z15*J15 -> 6288 | AC15: =AB15-AA15 -> 786
... A28: 24 | B28: =(PRECIOS!B28) -> TOCINO | C28: =SUM('ORDENES '!D55) -> 0.4 | D28: =SUM('ORDENES '!E55) -> 0 | E28: =SUM('ORDENES '!F55) -> 0.6 | F28: =SUM('ORDENES '!G55) -> 0 | G28: =SUM('ORDENES '!H55) -> 0 | H28: =SUM('ORDENES '!I55) -> 0.4 | I28: =SUM('ORDENES '!J55) -> 0 | J28: =SUM(C28:I28) -> 1.4 | K28: =SUM(C28*Y28) -> 36 | L28: =SUM(C28*Z28) -> 56 | M28: =SUM(D28*Y28) -> 0 | N28: =SUM(D28*Z28) -> 0 | O28: =SUM(E28*Y28) -> 54 | P28: =SUM(E28*Z28) -> 84 | Q28: =SUM(F28*Y28) -> 0 | R28: =SUM(F28*Z28) -> 0 | S28: =SUM(G28*Y28) -> 0 | T28: =SUM(G28*Z28) -> 0 | U28: =SUM(H28*Y28) -> 36 | V28: =SUM(H28*Z28) -> 56 | W28: =SUM(I28*Y28) -> 0 | X28: =SUM(I28*Z28) -> 0 | Y28: =SUM(PRECIOS!C28) -> 90 | Z28: =SUM(PRECIOS!D28) -> 140 | AA28: =Y28*J28 -> 126 | AB28: =Z28*J28 -> 196 | AC28: =AB28-AA28 -> 70
J29: =SUM(J4:J28) -> 390.89 | K29: =SUM(K4:K28) -> 3235.56 | L29: =SUM(L4:L28) -> 5814.75 | M29: =SUM(M4:M28) -> 3810.06 | N29: =SUM(N4:N28) -> 6455.85 | O29: =SUM(O4:O28) -> 3481.506 | P29: =SUM(P4:P28) -> 5265.7 | Q29: =SUM(Q4:Q28) -> 4228.92 | ... X29: =SUM(X4:X28) -> 6631.8 | AA29: =SUM(K29,M29,O29,Q29,S29,U29,W29) -> 25269.674 | AB29: =SUM(L29,N29,P29,R29,T29,V29,X29) -> 42436.2 | AC29: =SUM(AB29-AA29) -> 17166.526

Sheet GUARDERIA
C1: =('ORDENES '!L1) -> 11-17 enero
I2: GUARDERIA
A3: No. | B3: Producto | C3: Lunes | D3: Martes | E3: Miercoles | F3: Jueves | G3: Viernes | H3: Total / semana | I3: Imp. Lunes | J3: Nota Lunes | K3: Importe Martes | L3: Nota Martes | M3: Imp Miercoles | N3: Nota Miercoles | O3: Imp. Jueves | P3: Nota Jueves | Q3: Imp. Viernes | R3: Nota Viernes | S3: PRECIO COSTO | T3: PRECIO VENTA | U3: Total Compra | V3: Total Venta | W3: Utilidad
A4: 1 | B4: =(PRECIOS!B4) -> CHULETA DE CERDO | C4: =SUM('ORDENES '!O31) -> 0 | D4: =SUM('ORDENES '!P31) -> 0 | E4: =SUM('ORDENES '!Q31) -> 0 | F4: =SUM('ORDENES '!R31) -> 0 | G4: =SUM('ORDENES '!S31) -> 0 | H4: =SUM(C4:G4) -> 0 | I4: =SUM(C4*S4) -> 0 | J4: =SUM(C4*T4) -> 0 | K4: =SUM(D4*S4) -> 0 | L4: =SUM(D4*T4) -> 0 | M4: =SUM(E4*S4) -> 0 | N4: =SUM(E4*T4) -> 0 | O4: =SUM(F4*S4) -> 0 | P4: =SUM(F4*T4) -> 0 | Q4: =SUM(G4*S4) -> 0 | R4: =SUM(G4*T4) -> 0 | S4: =SUM(PRECIOS!C4) -> 89 | T4: =SUM(PRECIOS!D4) -> 89 | U4: =S4*H4 -> 0 | V4: =T4*H4 -> 0 | W4: =V4-U4 -> 0
A5: 2 | B5: =(PRECIOS!B5) -> LOMO DE CERDO | C5: =SUM('ORDENES '!O32) -> 0 | D5: =SUM('ORDENES '!P32) -> 6 | E5: =SUM('ORDENES '!Q32) -> 0 | F5: =SUM('ORDENES '!R32) -> 0 | G5: =SUM('ORDENES '!S32) -> 0 | H5: =SUM(C5:G5) -> 6 | I5: =SUM(C5*S5) -> 0 | J5: =SUM(C5*T5) -> 0 | K5: =SUM(D5*S5) -> 300 | L5: =SUM(D5*T5) -> 570 | M5: =SUM(E5*S5) -> 0 | N5: =SUM(E5*T5) -> 0 | O5: =SUM(F5*S5) -> 0 | P5: =SUM(F5*T5) -> 0 | Q5: =SUM(G5*S5) -> 0 | R5: =SUM(G5*T5) -> 0 | S5: =SUM(PRECIOS!C5) -> 50 | T5: =SUM(PRECIOS!D5) -> 95 | U5: =S5*H5 -> 300 | V5: =T5*H5 -> 570 | W5: =V5-U5 -> 270
A6: 3 | B6: =(PRECIOS!B6) -> PIERNA DE CERDO EN TROZO | C6: =SUM('ORDENES '!O33) -> 0 | D6: =SUM('ORDENES '!P33) -> 0 | E6: =SUM('ORDENES '!Q33) -> 0 | F6: =SUM('ORDENES '!R33) -> 0 | G6: =SUM('ORDENES '!S33) -> 0 | H6: =SUM(C6:G6) -> 0 | I6: =SUM(C6*S6) -> 0 | J6: =SUM(C6*T6) -> 0 | K6: =SUM(D6*S6) -> 0 | L6: =SUM(D6*T6) -> 0 | M6: =SUM(E6*S6) -> 0 | N6: =SUM(E6*T6) -> 0 | O6: =SUM(F6*S6) -> 0 | P6: =SUM(F6*T6) -> 0 | Q6: =SUM(G6*S6) -> 0 | R6: =SUM(G6*T6) -> 0 | S6: =SUM(PRECIOS!C6) -> 64 | T6: =SUM(PRECIOS!D6) -> 82 | U6: =S6*H6 -> 0 | V6: =T6*H6 -> 0 | W6: =V6-U6 -> 0
